Workbook

Sheet sheet1
A1: k | B1: 汇总统计
B3: 白班 | E3: 夜班 | H3: 总小时数 | I3: 调度席
A4: 目录 | B4: 带班 | C4: 席位 | D4: 教员 | E4: 带班 | F4: 席位 | G4: 教员
A5: 温若春 | B5: =温若春!K16 -> 46.084167 | C5: =温若春!K17 -> 15.318056 | D5: =温若春!K19 -> 0 | E5: =温若春!L16 -> 36.168611 | F5: =温若春!L17 -> 0 | G5: =温若春!L19 -> 0 | H5: =SUM(B5:G5) -> 97.570833 | I5: =温若春!J21 -> 0
A6: 明嘉 | B6: =明嘉!K16 -> 0 | C6: =明嘉!K17 -> 34.552778 | D6: =明嘉!K19 -> 0 | E6: =明嘉!L16 -> 0 | F6: =明嘉!L17 -> 25.772222 | G6: =明嘉!L19 -> 0 | H6: =SUM(B6:G6) -> 60.325 | I6: =明嘉!J21 -> 6.4166667
A7: 徐万友 | B7: =徐万友!K16 -> 69.830556 | C7: =徐万友!K17 -> 1.1502778 | D7: =徐万友!K19 -> 0 | E7: =徐万友!L16 -> 17.8225 | F7: =徐万友!L17 -> 3.5172222 | G7: =徐万友!L19 -> 0 | H7: =SUM(B7:G7) -> 92.320556 | I7: =徐万友!J21 -> 0
A8: 耿若岩 | B8: =耿若岩!K16 -> 0 | C8: =耿若岩!K17 -> 33.312222 | D8: =耿若岩!K19 -> 0 | E8: =耿若岩!L16 -> 0 | F8: =耿若岩!L17 -> 13.359167 | G8: =耿若岩!L19 -> 0 | H8: =SUM(B8:G8) -> 46.671389 | I8: =耿若岩!J21 -> 4.3319444
A9: 李明 | B9: =李明!K16 -> 0 | C9: =李明!K17 -> 49.227222 | D9: =李明!K19 -> 0 | E9: =李明!L16 -> 0 | F9: =李明!L17 -> 31.446389 | G9: =李明!L19 -> 0 | H9: =SUM(B9:G9) -> 80.673611 | I9: =李明!J21 -> 13.668889
A10: 张虎 | B10: =张虎!K16 -> 0 | C10: =张虎!K17 -> 30.106667 | D10: =张虎!K19 -> 0 | E10: =张虎!L16 -> 0 | F10: =张虎!L17 -> 19.820278 | G10: =张虎!L19 -> 0 | H10: =SUM(B10:G10) -> 49.926944 | I10: =张虎!J21 -> 0
A11: 马莲花 | B11: =马莲花!K16 -> 40.656944 | C11: =马莲花!K17 -> 20.414444 | D11: =马莲花!K19 -> 0 | E11: =马莲花!L16 -> 17.594167 | F11: =马莲花!L17 -> 6.5655556 | G11: =马莲花!L19 -> 0 | H11: =SUM(B11:G11) -> 85.231111 | I11: =马莲花!J21 -> 0
A12: 刘国莲 | B12: =刘国莲!K15 -> 0 | C12: =刘国莲!K16 -> 40.127778 | D12: =刘国莲!K18 -> 0 | E12: =刘国莲!L15 -> 0 | F12: =刘国莲!L16 -> 33.026389 | G12: =刘国莲!L18 -> 0 | H12: =SUM(B12:G12) -> 73.154167 | I12: =刘国莲!J20 -> 7.3677778
A13: 杜涛 | B13: =杜涛!K16 -> 0 | C13: =杜涛!K17 -> 43.485556 | D13: =杜涛!K19 -> 0 | E13: =杜涛!L16 -> 0 | F13: =杜涛!L17 -> 27.347778 | G13: =杜涛!L19 -> 0 | H13: =SUM(B13:G13) -> 70.833333 | I13: =杜涛!J21 -> 6.515
A14: 张文中 | B14: =张文中!K16 -> 0 | C14: =张文中!K17 -> 37.504167 | D14: =张文中!K19 -> 0 | E14: =张文中!L16 -> 0 | F14: =张文中!L17 -> 35.405 | G14: =张文中!L19 -> 0 | H14: =SUM(B14:G14) -> 72.909167 | I14: =张文中!J21 -> 9.0830556
A15: 李秋实 | B15: =李秋实!K16 -> 0 | C15: =李秋实!K17 -> 34.314722 | D15: =李秋实!K19 -> 0 | E15: =李秋实!L16 -> 0 | F15: =李秋实!L17 -> 29.284722 | G15: =李秋实!L19 -> 0 | H15: =SUM(B15:G15) -> 63.599444 | I15: =李秋实!J21 -> 15.586667
A16: 周岸 | B16: =周岸!K16 -> 0 | C16: =周岸!K17 -> 32.322778 | D16: =周岸!K19 -> 0 | E16: =周岸!L16 -> 0 | F16: =周岸!L17 -> 33.0525 | G16: =周岸!L19 -> 0 | H16: =SUM(B16:G16) -> 65.375278 | I16: =周岸!J21 -> 0
A17: 詹泽彬 | B17: =詹泽彬!K16 -> 0 | C17: =詹泽彬!K17 -> 30.176389 | D17: =詹泽彬!K19 -> 0 | E17: =詹泽彬!L16 -> 0 | F17: =詹泽彬!L17 -> 28.963056 | G17: =詹泽彬!L19 -> 0 | H17: =SUM(B17:G17) -> 59.139444 | I17: =詹泽彬!J21 -> 5.7352778
A18: 张笑延 | B18: =张笑延!K16 -> 0 | C18: =张笑延!K17 -> 45.05 | D18: =张笑延!K19 -> 0 | E18: =张笑延!L16 -> 0 | F18: =张笑延!L17 -> 23.813333 | G18: =张笑延!L19 -> 0 | H18: =SUM(B18:G18) -> 68.863333 | I18: =张笑延!J21 -> 5.1108333
A19: 沈宁 | B19: =沈宁!K16 -> 0 | C19: =沈宁!K17 -> 33.520278 | D19: =沈宁!K19 -> 0 | E19: =沈宁!L16 -> 0 | F19: =沈宁!L17 -> 21.706667 | G19: =沈宁!L19 -> 0 | H19: =SUM(B19:G19) -> 55.226944 | I19: =沈宁!J21 -> 4.6697222
A20: 胡鑫 | B20: =胡鑫!K16 -> 55.819722 | C20: =胡鑫!K17 -> 8.3866667 | D20: =胡鑫!K19 -> 0 | E20: =胡鑫!L16 -> 31.764167 | F20: =胡鑫!L17 -> 6.7236111 | G20: =胡鑫!L19 -> 0 | H20: =SUM(B20:G20) -> 102.69417 | I20: =胡鑫!J21 -> 0
A21: 邓心豪 | B21: =邓心豪!K16 -> 0 | C21: =邓心豪!K17 -> 33.776944 | D21: =邓心豪!K19 -> 0 | E21: =邓心豪!L16 -> 0 | F21: =邓心豪!L17 -> 30.288889 | G21: =邓心豪!L19 -> 0 | H21: =SUM(B21:G21) -> 64.065833 | I21: =邓心豪!J21 -> 0
A22: 黄恩 | B22: =黄恩!K16 -> 0 | C22: =黄恩!K17 -> 52.577222 | D22: =黄恩!K19 -> 0 | E22: =黄恩!L16 -> 0 | F22: =黄恩!L17 -> 15.386944 | G22: =黄恩!L19 -> 0 | H22: =SUM(B22:G22) -> 67.964167 | I22: =黄恩!J21 -> 0
A23: 严亮 | B23: =严亮!K16 -> 0 | C23: =严亮!K17 -> 31.477222 | D23: =严亮!K19 -> 0 | E23: =严亮!L16 -> 0 | F23: =严亮!L17 -> 22.199444 | G23: =严亮!L19 -> 0 | H23: =SUM(B23:G23) -> 53.676667 | I23: =严亮!J21 -> 11.333056
A24: 边昊 | B24: =边昊!K16 -> 37.695833 | C24: =边昊!K17 -> 13.916389 | D24: =边昊!K19 -> 0 | E24: =边昊!L16 -> 9.5455556 | F24: =边昊!L17 -> 12.064444 | G24: =边昊!L19 -> 0 | H24: =SUM(B24:G24) -> 73.222222 | I24: =边昊!J21 -> 0
A25: 张宗根 | B25: =张宗根!K16 -> 0 | C25: =张宗根!K17 -> 32.305278 | D25: =张宗根!K19 -> 0 | E25: =张宗根!L16 -> 0 | F25: =张宗根!L17 -> 29.075833 | G25: =张宗根!L19 -> 0 | H25: =SUM(B25:G25) -> 61.381111 | I25: =张宗根!J21 -> 0
A26: 宋天霖 | B26: =宋天霖!K16 -> 0 | C26: =宋天霖!K17 -> 0 | D26: =宋天霖!K19 -> 0 | E26: =宋天霖!L16 -> 0 | F26: =宋天霖!L17 -> 0 | G26: =宋天霖!L19 -> 0 | H26: =SUM(B26:G26) -> 0 | I26: =宋天霖!J21 -> 0
A27: 蔡昊霖 | B27: =蔡昊霖!K16 -> 0 | C27: =蔡昊霖!K17 -> 32.121389 | D27: =蔡昊霖!K19 -> 0 | E27: =蔡昊霖!L16 -> 0 | F27: =蔡昊霖!L17 -> 16.427222 | G27: =蔡昊霖!L19 -> 0 | H27: =SUM(B27:G27) -> 48.548611 | I27: =蔡昊霖!J21 -> 0
A28: 叶大鹏 | B28: =叶大鹏!K16 -> 0 | C28: =叶大鹏!K17 -> 18.730278 | D28: =叶大鹏!K19 -> 0 | E28: =叶大鹏!L16 -> 0 | F28: =叶大鹏!L17 -> 18.597778 | G28: =叶大鹏!L19 -> 0 | H28: =SUM(B28:G28) -> 37.328056 | I28: =叶大鹏!J21 -> 12.556111
A29: 王建超 | B29: =王建超!K16 -> 0 | C29: =王建超!K17 -> 34.414444 | D29: =王建超!K19 -> 0 | E29: =王建超!L16 -> 0 | F29: =王建超!L17 -> 29.140833 | G29: =王建超!L19 -> 0 | H29: =SUM(B29:G29) -> 63.555278 | I29: =王建超!J21 -> 11.673333
A30: 潘伟生 | B30: =潘伟生!K16 -> 0 | C30: =潘伟生!K17 -> 28.511944 | D30: =潘伟生!K19 -> 0 | E30: =潘伟生!L16 -> 0 | F30: =潘伟生!L17 -> 23.319167 | G30: =潘伟生!L19 -> 0 | H30: =SUM(B30:G30) -> 51.831111 | I30: =潘伟生!J21 -> 6.8325
A31: 王风瑞 | B31: =王风瑞!K16 -> 0 | C31: =王风瑞!K17 -> 49.672222 | D31: =王风瑞!K19 -> 0 | E31: =王风瑞!L16 -> 0 | F31: =王风瑞!L17 -> 36.069167 | G31: =王风瑞!L19 -> 0 | H31: =SUM(B31:G31) -> 85.741389 | I31: =王风瑞!J21 -> 4.9883333
A32: 金鼎 | B32: =金鼎!K16 -> 52.912778 | C32: =金鼎!K17 -> 8.6663889 | D32: =金鼎!K19 -> 0 | E32: =金鼎!L16 -> 28.543611 | F32: =金鼎!L17 -> 3.7691667 | G32: =金鼎!L19 -> 0 | H32: =SUM(B32:G32) -> 93.891944 | I32: =金鼎!J21 -> 0
A33: 董志华 | B33: =董志华!K16 -> 37.590278 | C33: =董志华!K17 -> 0 | D33: =董志华!K19 -> 0 | E33: =董志华!L16 -> 35.2575 | F33: =董志华!L17 -> 0 | G33: =董志华!L19 -> 0 | H33: =SUM(B33:G33) -> 72.847778 | I33: =董志华!J21 -> 0
A34: 姜文夫 | B34: =姜文夫!K16 -> 54.621424 | C34: =姜文夫!K17 -> 16.051111 | D34: =姜文夫!K19 -> 0 | E34: =姜文夫!L16 -> 29.416389 | F34: =姜文夫!L17 -> 0.815 | G34: =姜文夫!L19 -> 0 | H34: =SUM(B34:G34) -> 100.90392 | I34: =姜文夫!J21 -> 0
A35: 郭永杰 | B35: =郭永杰!K16 -> 46.325833 | C35: =郭永杰!K17 -> 8.0938889 | D35: =郭永杰!K19 -> 0 | E35: =郭永杰!L16 -> 25.359444 | F35: =郭永杰!L17 -> 14.354167 | G35: =郭永杰!L19 -> 0 | H35: =SUM(B35:G35) -> 94.133333 | I35: =郭永杰!J21 -> 0
A36: 朱永春 | B36: =朱永春!K16 -> 0 | C36: =朱永春!K17 -> 29.420833 | D36: =朱永春!K19 -> 0 | E36: =朱永春!L16 -> 0 | F36: =朱永春!L17 -> 33.938056 | G36: =朱永春!L19 -> 0 | H36: =SUM(B36:G36) -> 63.358889 | I36: =朱永春!J21 -> 10.896389
A37: 刘琦 | B37: =刘琦!K16 -> 0 | C37: =刘琦!K17 -> 46.2875 | D37: =刘琦!K19 -> 0 | E37: =刘琦!L16 -> 0 | F37: =刘琦!L17 -> 0.41361111 | G37: =刘琦!L19 -> 0 | H37: =SUM(B37:G37) -> 46.701111 | I37: =刘琦!J21 -> 0
A38: 吴疆 | B38: =吴疆!K16 -> 60.734167 | C38: =吴疆!K17 -> 6.3144444 | D38: =吴疆!K19 -> 0 | E38: =吴疆!L16 -> 28.916111 | F38: =吴疆!L17 -> 12.113056 | G38: =吴疆!L19 -> 0 | H38: =SUM(B38:G38) -> 108.07778 | I38: =吴疆!J21 -> 0
A39: 巴富毅 | B39: =巴富毅!K16 -> 0 | C39: =巴富毅!K17 -> 29.051667 | D39: =巴富毅!K19 -> 0 | E39: =巴富毅!L16 -> 0 | F39: =巴富毅!L17 -> 1.6025 | G39: =巴富毅!L19 -> 0 | H39: =SUM(B39:G39) -> 30.654167 | I39: =巴富毅!J21 -> 0
A40: 陈宏伟 | B40: =陈宏伟!K16 -> 0 | C40: =陈宏伟!K17 -> 41.370556 | D40: =陈宏伟!K19 -> 0 | E40: =陈宏伟!L16 -> 0 | F40: =陈宏伟!L17 -> 33.455556 | G40: =陈宏伟!L19 -> 0 | H40: =SUM(B40:G40) -> 74.826111 | I40: =陈宏伟!J21 -> 0
A41: 蒋露裕 | B41: =蒋露裕!K16 -> 0 | C41: =蒋露裕!K17 -> 17.641667 | D41: =蒋露裕!K19 -> 0 | E41: =蒋露裕!L16 -> 0 | F41: =蒋露裕!L17 -> 26.516944 | G41: =蒋露裕!L19 -> 0 | H41: =SUM(B41:G41) -> 44.158611 | I41: =蒋露裕!J21 -> 7.5569444
...

Sheet 温若春
A1: 返回目录
A2: 日 期 | B2: 岗 位 | C2: 上岗时刻 | D2: 交接班 | E2: 离岗时刻 | F2: 时段工作小时 | G2: 白班小时 | H2: 夜班小时 (0200-0800) | I2: 统 计 | J2: 各席位总小时 | K2: 白班小时 | L2: 夜班小时 (0000-0800) | M2: 备注
A3: =IF(B3="","",IF(A3="",NOW(),A3)) -> 46205.132 | B3: 带班主任 | C3: 0.13228009 | D3: 完成 | E3: 0.30359954 | F3: =(IF(E3-C3<0,"24:00"-C3+E3,E3-C3))*24 -> 4.1116667 | G3: =F3-H3 -> 0 | H3: =(IF(AND(C3>=$O$3,C3<$P$3,E3>=$O$3,E3<$P$3),E3-C3,IF(AND(C3>=$O$3,C3<$P$3,E3>=$P$3,E3<$N$3),$P$3-C3,IF(AND(C3>=$P$3,C3<$N$3,E3>=$O$3,E3<$P$3),E3,IF(AND(C3>=$P$3,C3<$N$3,E3>=$P$3,E3<$N$3),"0","none")))))*24 -> 4.1116667 | I3: 带班主任席执勤小时 | J3: =SUMIF(B:B,"带班主任",F:F) -> 82.252778 | K3: =SUMIF(B:B,"带班主任",G:G) -> 46.084167 | L3: =SUMIF(B:B,"带班主任",H:H) -> 36.168611 | N3: 0.99998843 | O3: 0 | P3: 0.33333333
A4: =IF(B4="","",IF(A4="",NOW(),A4)) -> 46205.947 | B4: 带班主任 | C4: 0.94694444 | D4: 完成 | E4: 0.13936343 | F4: =(IF(E4-C4<0,"24:00"-C4+E4,E4-C4))*24 -> 4.6180556 | G4: =F4-H4 -> 1.2733333 | H4: =(IF(AND(C4>=$O$3,C4<$P$3,E4>=$O$3,E4<$P$3),E4-C4,IF(AND(C4>=$O$3,C4<$P$3,E4>=$P$3,E4<$N$3),$P$3-C4,IF(AND(C4>=$P$3,C4<$N$3,E4>=$O$3,E4<$P$3),E4,IF(AND(C4>=$P$3,C4<$N$3,E4>=$P$3,E4<$N$3),"0","none")))))*24 -> 3.3447222 | I4: 机场管制席执勤小时 | J4: =SUMIF(B:B,"西塔台管制席",F:F)+SUMIF(B:B,"东塔台管制席",F:F) -> 8.8958333 | K4: =SUMIF(B:B,"西塔台管制席",G:G)+SUMIF(B:B,"东塔台管制席",G:G) -> 8.8958333 | L4: =SUMIF(B:B,"西塔台管制席",H:H)+SUMIF(B:B,"东塔台管制席",H:H) -> 0
A5: =IF(B5="","",IF(A5="",NOW(),A5)) -> 46208.502 | B5: 东塔台协调席 | C5: 0.50049769 | D5: 完成 | E5: 0.6362037 | F5: =(IF(E5-C5<0,"24:00"-C5+E5,E5-C5))*24 -> 3.2569444 | G5: =F5-H5 -> 3.2569444 | H5: =(IF(AND(C5>=$O$3,C5<$P$3,E5>=$O$3,E5<$P$3),E5-C5,IF(AND(C5>=$O$3,C5<$P$3,E5>=$P$3,E5<$N$3),$P$3-C5,IF(AND(C5>=$P$3,C5<$N$3,E5>=$O$3,E5<$P$3),E5,IF(AND(C5>=$P$3,C5<$N$3,E5>=$P$3,E5<$N$3),"0","none")))))*24 -> 0 | I5: 机场协调席执勤小时 | J5: =SUMIF(B:B,"西塔台协调席",F:F)+SUMIF(B:B,"东塔台协调席",F:F) -> 6.4222222 | K5: =SUMIF(B:B,"西塔台协调席",G:G)+SUMIF(B:B,"东塔台协调席",G:G) -> 6.4222222 | L5: =SUMIF(B:B,"西塔台协调席",H:H)+SUMIF(B:B,"东塔台协调席",H:H) -> 0
A6: =IF(B6="","",IF(A6="",NOW(),A6)) -> 46208.752 | B6: 西塔台管制席 | C6: 0.75194444 | D6: 完成 | E6: 0.88313657 | F6: =(IF(E6-C6<0,"24:00"-C6+E6,E6-C6))*24 -> 3.1486111 | G6: =F6-H6 -> 3.1486111 | H6: =(IF(AND(C6>=$O$3,C6<$P$3,E6>=$O$3,E6<$P$3),E6-C6,IF(AND(C6>=$O$3,C6<$P$3,E6>=$P$3,E6<$N$3),$P$3-C6,IF(AND(C6>=$P$3,C6<$N$3,E6>=$O$3,E6<$P$3),E6,IF(AND(C6>=$P$3,C6<$N$3,E6>=$P$3,E6<$N$3),"0","none")))))*24 -> 0 | I6: 放行席执勤小时 | J6: =SUMIF(B:B,"放行席",F:F) -> 0 | K6: =SUMIF(B:B,"放行席",G:G) -> 0 | L6: =SUMIF(B:B,"放行席",H:H) -> 0
A7: =IF(B7="","",IF(A7="",NOW(),A7)) -> 46209.293 | B7: 带班主任 | C7: 0.29303241 | D7: 完成 | E7: 0.33903935 | F7: =(IF(E7-C7<0,"24:00"-C7+E7,E7-C7))*24 -> 1.1041667 | G7: =F7-H7 -> 0.13694444 | H7: =(IF(AND(C7>=$O$3,C7<$P$3,E7>=$O$3,E7<$P$3),E7-C7,IF(AND(C7>=$O$3,C7<$P$3,E7>=$P$3,E7<$N$3),$P$3-C7,IF(AND(C7>=$P$3,C7<$N$3,E7>=$O$3,E7<$P$3),E7,IF(AND(C7>=$P$3,C7<$N$3,E7>=$P$3,E7<$N$3),"0","none")))))*24 -> 0.96722222 | I7: 地面席执勤小时 | J7: =SUMIF(B:B,"地面席",F:F) -> 0 | K7: =SUMIF(B:B,"地面席",G:G) -> 0 | L7: =SUMIF(B:B,"地面席",H:H) -> 0
A8: =IF(B8="","",IF(A8="",NOW(),A8)) -> 46209.346 | B8: 带班主任 | C8: 0.34616898 | D8: 完成 | E8: 0.51611111 | F8: =(IF(E8-C8<0,"24:00"-C8+E8,E8-C8))*24 -> 4.0786111 | G8: =F8-H8 -> 4.0786111 | H8: =(IF(AND(C8>=$O$3,C8<$P$3,E8>=$O$3,E8<$P$3),E8-C8,IF(AND(C8>=$O$3,C8<$P$3,E8>=$P$3,E8<$N$3),$P$3-C8,IF(AND(C8>=$P$3,C8<$N$3,E8>=$O$3,E8<$P$3),E8,IF(AND(C8>=$P$3,C8<$N$3,E8>=$P$3,E8<$N$3),"0","none")))))*24 -> 0 | I8: 生产调度席执勤小时 | J8: =SUMIF(B:B,"生产调度席",F:F) -> 0 | K8: =SUMIF(B:B,"生产调度席",G:G) -> 0 | L8: =SUMIF(B:B,"生产调度席",H:H) -> 0
A9: =IF(B9="","",IF(A9="",NOW(),A9)) -> 46209.527 | B9: 带班主任 | C9: 0.52696759 | D9: 完成 | E9: 0.53594907 | F9: =(IF(E9-C9<0,"24:00"-C9+E9,E9-C9))*24 -> 0.21555556 | G9: =F9-H9 -> 0.21555556 | H9: =(IF(AND(C9>=$O$3,C9<$P$3,E9>=$O$3,E9<$P$3),E9-C9,IF(AND(C9>=$O$3,C9<$P$3,E9>=$P$3,E9<$N$3),$P$3-C9,IF(AND(C9>=$P$3,C9<$N$3,E9>=$O$3,E9<$P$3),E9,IF(AND(C9>=$P$3,C9<$N$3,E9>=$P$3,E9<$N$3),"0","none")))))*24 -> 0 | I9: 航班调度席执勤小时 | J9: =SUMIF(B:B,"航班调度席",F:F) -> 0 | K9: =SUMIF(B:B,"航班调度席",G:G) -> 0 | L9: =SUMIF(B:B,"航班调度席",H:H) -> 0
A10: =IF(B10="","",IF(A10="",NOW(),A10)) -> 46209.939 | B10: 带班主任 | C10: 0.93928241 | D10: 完成 | E10: 0.13961806 | F10: =(IF(E10-C10<0,"24:00"-C10+E10,E10-C10))*24 -> 4.8080556 | G10: =F10-H10 -> 1.4572222 | H10: =(IF(AND(C10>=$O$3,C10<$P$3,E10>=$O$3,E10<$P$3),E10-C10,IF(AND(C10>=$O$3,C10<$P$3,E10>=$P$3,E10<$N$3),$P$3-C10,IF(AND(C10>=$P$3,C10<$N$3,E10>=$O$3,E10<$P$3),E10,IF(AND(C10>=$P$3,C10<$N$3,E10>=$P$3,E10<$N$3),"0","none")))))*24 -> 3.3508333 | I10: 综合协调席小时 | J10: =SUMIF(B:B,"综合协调席",F:F) -> 0 | K10: =SUMIF(B:B,"综合协调席",G:G) -> 0 | L10: =SUMIF(B:B,"综合协调席",H:H) -> 0
A11: =IF(B11="","",IF(A11="",NOW(),A11)) -> 46213.292 | B11: 带班主任 | C11: 0.29219907 | D11: 完成 | E11: 0.33503472 | F11: =(IF(E11-C11<0,"24:00"-C11+E11,E11-C11))*24 -> 1.0280556 | G11: =F11-H11 -> 0.040833333 | H11: =(IF(AND(C11>=$O$3,C11<$P$3,E11>=$O$3,E11<$P$3),E11-C11,IF(AND(C11>=$O$3,C11<$P$3,E11>=$P$3,E11<$N$3),$P$3-C11,IF(AND(C11>=$P$3,C11<$N$3,E11>=$O$3,E11<$P$3),E11,IF(AND(C11>=$P$3,C11<$N$3,E11>=$P$3,E11<$N$3),"0","none")))))*24 -> 0.98722222 | I11: 见习管制员小时 | J11: =SUMIF(B:B,"见习管制员",F:F) -> 0 | K11: =SUMIF(B:B,"见习管制员",G:G) -> 0 | L11: =SUMIF(B:B,"见习管制员",H:H) -> 0
A12: =IF(B12="","",IF(A12="",NOW(),A12)) -> 46213.343 | B12: 带班主任 | C12: 0.34275463 | D12: 完成 | E12: 0.46391204 | F12: =(IF(E12-C12<0,"24:00"-C12+E12,E12-C12))*24 -> 2.9077778 | G12: =F12-H12 -> 2.9077778 | H12: =(IF(AND(C12>=$O$3,C12<$P$3,E12>=$O$3,E12<$P$3),E12-C12,IF(AND(C12>=$O$3,C12<$P$3,E12>=$P$3,E12<$N$3),$P$3-C12,IF(AND(C12>=$P$3,C12<$N$3,E12>=$O$3,E12<$P$3),E12,IF(AND(C12>=$P$3,C12<$N$3,E12>=$P$3,E12<$N$3),"0","none")))))*24 -> 0 | I12: 管制教员席小时 | J12: =SUMIF(B:B,"管制教员席",F:F) -> 0 | K12: =SUMIF(B:B,"管制教员席",G:G) -> 0 | L12: =SUMIF(B:B,"管制教员席",H:H) -> 0
A13: =IF(B13="","",IF(A13="",NOW(),A13)) -> 46213.473 | B13: 带班主任 | C13: 0.47297454 | D13: 完成 | E13: 0.54252315 | F13: =(IF(E13-C13<0,"24:00"-C13+E13,E13-C13))*24 -> 1.6691667 | G13: =F13-H13 -> 1.6691667 | H13: =(IF(AND(C13>=$O$3,C13<$P$3,E13>=$O$3,E13<$P$3),E13-C13,IF(AND(C13>=$O$3,C13<$P$3,E13>=$P$3,E13<$N$3),$P$3-C13,IF(AND(C13>=$P$3,C13<$N$3,E13>=$O$3,E13<$P$3),E13,IF(AND(C13>=$P$3,C13<$N$3,E13>=$P$3,E13<$N$3),"0","none")))))*24 -> 0 | I13: 月度总小时统计
A14: =IF(B14="","",IF(A14="",NOW(),A14)) -> 46213.939 | B14: 带班主任 | C14: 0.93875 | D14: 完成 | E14: 0.13938657 | F14: =(IF(E14-C14<0,"24:00"-C14+E14,E14-C14))*24 -> 4.8152778 | G14: =F14-H14 -> 1.47 | H14: =(IF(AND(C14>=$O$3,C14<$P$3,E14>=$O$3,E14<$P$3),E14-C14,IF(AND(C14>=$O$3,C14<$P$3,E14>=$P$3,E14<$N$3),$P$3-C14,IF(AND(C14>=$P$3,C14<$N$3,E14>=$O$3,E14<$P$3),E14,IF(AND(C14>=$P$3,C14<$N$3,E14>=$P$3,E14<$N$3),"0","none")))))*24 -> 3.3452778
A15: =IF(B15="","",IF(A15="",NOW(),A15)) -> 46216.525 | B15: 带班主任 | C15: 0.52488426 | D15: 完成 | E15: 0.65501157 | F15: =(IF(E15-C15<0,"24:00"-C15+E15,E15-C15))*24 -> 3.1230556 | G15: =F15-H15 -> 3.1230556 | H15: =(IF(AND(C15>=$O$3,C15<$P$3,E15>=$O$3,E15<$P$3),E15-C15,IF(AND(C15>=$O$3,C15<$P$3,E15>=$P$3,E15<$N$3),$P$3-C15,IF(AND(C15>=$P$3,C15<$N$3,E15>=$O$3,E15<$P$3),E15,IF(AND(C15>=$P$3,C15<$N$3,E15>=$P$3,E15<$N$3),"0","none")))))*24 -> 0 | I15: 统计 | J15: 各席位总小时 | K15: 白班小时 | L15: 夜班小时 (0000-0800) | M15: 备注
A16: =IF(B16="","",IF(A16="",NOW(),A16)) -> 46216.773 | B16: 带班主任 | C16: 0.77258102 | D16: 完成 | E16: 0.94581019 | F16: =(IF(E16-C16<0,"24:00"-C16+E16,E16-C16))*24 -> 4.1575 | G16: =F16-H16 -> 4.1575 | H16: =(IF(AND(C16>=$O$3,C16<$P$3,E16>=$O$3,E16<$P$3),E16-C16,IF(AND(C16>=$O$3,C16<$P$3,E16>=$P$3,E16<$N$3),$P$3-C16,IF(AND(C16>=$P$3,C16<$N$3,E16>=$O$3,E16<$P$3),E16,IF(AND(C16>=$P$3,C16<$N$3,E16>=$P$3,E16<$N$3),"0","none")))))*24 -> 0 | I16: 带班主任席执勤小时 | J16: =J3 -> 82.252778 | K16: =K3 -> 46.084167 | L16: =L3 -> 36.168611
A17: =IF(B17="","",IF(A17="",NOW(),A17)) -> 46217.293 | B17: 带班主任 | C17: 0.2934838 | D17: 完成 | E17: 0.35484954 | F17: =(IF(E17-C17<0,"24:00"-C17+E17,E17-C17))*24 -> 1.4727778 | G17: =F17-H17 -> 0.51638889 | H17: =(IF(AND(C17>=$O$3,C17<$P$3,E17>=$O$3,E17<$P$3),E17-C17,IF(AND(C17>=$O$3,C17<$P$3,E17>=$P$3,E17<$N$3),$P$3-C17,IF(AND(C17>=$P$3,C17<$N$3,E17>=$O$3,E17<$P$3),E17,IF(AND(C17>=$P$3,C17<$N$3,E17>=$P$3,E17<$N$3),"0","none")))))*24 -> 0.95638889 | I17: 席位执勤小时 | J17: =J4+J5+J6+J7+J10 -> 15.318056 | K17: =K4+K5+K6+K7+K10 -> 15.318056 | L17: =L4+L5+L6+L7+L10 -> 0
A18: =IF(B18="","",IF(A18="",NOW(),A18)) -> 46217.36 | B18: 带班主任 | C18: 0.36030093 | D18: 完成 | E18: 0.4946875 | F18: =(IF(E18-C18<0,"24:00"-C18+E18,E18-C18))*24 -> 3.2252778 | G18: =F18-H18 -> 3.2252778 | H18: =(IF(AND(C18>=$O$3,C18<$P$3,E18>=$O$3,E18<$P$3),E18-C18,IF(AND(C18>=$O$3,C18<$P$3,E18>=$P$3,E18<$N$3),$P$3-C18,IF(AND(C18>=$P$3,C18<$N$3,E18>=$O$3,E18<$P$3),E18,IF(AND(C18>=$P$3,C18<$N$3,E18>=$P$3,E18<$N$3),"0","none")))))*24 -> 0 | I18: 见习管制员小时 | J18: =J11 -> 0 | K18: =K11 -> 0 | L18: =L11 -> 0
A19: =IF(B19="","",IF(A19="",NOW(),A19)) -> 46217.507 | B19: 带班主任 | C19: 0.5066088 | D19: 完成 | E19: 0.52961806 | F19: =(IF(E19-C19<0,"24:00"-C19+E19,E19-C19))*24 -> 0.55222222 | G19: =F19-H19 -> 0.55222222 | H19: =(IF(AND(C19>=$O$3,C19<$P$3,E19>=$O$3,E19<$P$3),E19-C19,IF(AND(C19>=$O$3,C19<$P$3,E19>=$P$3,E19<$N$3),$P$3-C19,IF(AND(C19>=$P$3,C19<$N$3,E19>=$O$3,E19<$P$3),E19,IF(AND(C19>=$P$3,C19<$N$3,E19>=$P$3,E19<$N$3),"0","none")))))*24 -> 0 | I19: 管制教员小时 | J19: =J12 -> 0 | K19: =K12 -> 0 | L19: =L12 -> 0
A20: =IF(B20="","",IF(A20="",NOW(),A20)) -> 46217.648 | B20: 带班主任 | C20: 0.64769676 | D20: 完成 | E20: 0.78813657 | F20: =(IF(E20-C20<0,"24:00"-C20+E20,E20-C20))*24 -> 3.3705556 | G20: =F20-H20 -> 3.3705556 | H20: =(IF(AND(C20>=$O$3,C20<$P$3,E20>=$O$3,E20<$P$3),E20-C20,IF(AND(C20>=$O$3,C20<$P$3,E20>=$P$3,E20<$N$3),$P$3-C20,IF(AND(C20>=$P$3,C20<$N$3,E20>=$O$3,E20<$P$3),E20,IF(AND(C20>=$P$3,C20<$N$3,E20>=$P$3,E20<$N$3),"0","none")))))*24 -> 0 | I20: 月度总小时 | J20: =J16+J17+J18+J19 -> 97.570833
A21: =IF(B21="","",IF(A21="",NOW(),A21)) -> 46220.938 | B21: 带班主任 | C21: 0.93829861 | D21: 完成 | E21: 0.14196759 | F21: =(IF(E21-C21<0,"24:00"-C21+E21,E21-C21))*24 -> 4.8880556 | G21: =F21-H21 -> 1.4808333 | H21: =(IF(AND(C21>=$O$3,C21<$P$3,E21>=$O$3,E21<$P$3),E21-C21,IF(AND(C21>=$O$3,C21<$P$3,E21>=$P$3,E21<$N$3),$P$3-C21,IF(AND(C21>=$P$3,C21<$N$3,E21>=$O$3,E21<$P$3),E21,IF(AND(C21>=$P$3,C21<$N$3,E21>=$P$3,E21<$N$3),"0","none")))))*24 -> 3.4072222 | I21: 调度席 | J21: =SUM(J8:J9) -> 0 | K21: =SUM(K8:K9) -> 0 | L21: =SUM(L8:L9) -> 0
A22: =IF(B22="","",IF(A22="",NOW(),A22)) -> 46222.135 | B22: 带班主任 | C22: 0.13461806 | D22: 完成 | E22: 0.30509259 | F22: =(IF(E22-C22<0,"24:00"-C22+E22,E22-C22))*24 -> 4.0913889 | G22: =F22-H22 -> 0 | H22: =(IF(AND(C22>=$O$3,C22<$P$3,E22>=$O$3,E22<$P$3),E22-C22,IF(AND(C22>=$O$3,C22<$P$3,E22>=$P$3,E22<$N$3),$P$3-C22,IF(AND(C22>=$P$3,C22<$N$3,E22>=$O$3,E22<$P$3),E22,IF(AND(C22>=$P$3,C22<$N$3,E22>=$P$3,E22<$N$3),"0","none")))))*24 -> 4.0913889
A23: =IF(B23="","",IF(A23="",NOW(),A23)) -> 46225.132 | B23: 带班主任 | C23: 0.13179398 | D23: 完成 | E23: 0.29810185 | F23: =(IF(E23-C23<0,"24:00"-C23+E23,E23-C23))*24 -> 3.9913889 | G23: =F23-H23 -> 0 | H23: =(IF(AND(C23>=$O$3,C23<$P$3,E23>=$O$3,E23<$P$3),E23-C23,IF(AND(C23>=$O$3,C23<$P$3,E23>=$P$3,E23<$N$3),$P$3-C23,IF(AND(C23>=$P$3,C23<$N$3,E23>=$O$3,E23<$P$3),E23,IF(AND(C23>=$P$3,C23<$N$3,E23>=$P$3,E23<$N$3),"0","none")))))*24 -> 3.9913889
A24: =IF(B24="","",IF(A24="",NOW(),A24)) -> 46225.938 | B24: 带班主任 | C24: 0.93831019 | D24: 完成 | E24: 0.13899306 | F24: =(IF(E24-C24<0,"24:00"-C24+E24,E24-C24))*24 -> 4.8163889 | G24: =F24-H24 -> 1.4805556 | H24: =(IF(AND(C24>=$O$3,C24<$P$3,E24>=$O$3,E24<$P$3),E24-C24,IF(AND(C24>=$O$3,C24<$P$3,E24>=$P$3,E24<$N$3),$P$3-C24,IF(AND(C24>=$P$3,C24<$N$3,E24>=$O$3,E24<$P$3),E24,IF(AND(C24>=$P$3,C24<$N$3,E24>=$P$3,E24<$N$3),"0","none")))))*24 -> 3.3358333
A25: =IF(B25="","",IF(A25="",NOW(),A25)) -> 46228.353 | B25: 西塔台管制席 | C25: 0.35297454 | D25: 完成 | E25: 0.50886574 | F25: =(IF(E25-C25<0,"24:00"-C25+E25,E25-C25))*24 -> 3.7413889 | G25: =F25-H25 -> 3.7413889 | H25: =(IF(AND(C25>=$O$3,C25<$P$3,E25>=$O$3,E25<$P$3),E25-C25,IF(AND(C25>=$O$3,C25<$P$3,E25>=$P$3,E25<$N$3),$P$3-C25,IF(AND(C25>=$P$3,C25<$N$3,E25>=$O$3,E25<$P$3),E25,IF(AND(C25>=$P$3,C25<$N$3,E25>=$P$3,E25<$N$3),"0","none")))))*24 -> 0
A26: =IF(B26="","",IF(A26="",NOW(),A26)) -> 46228.625 | B26: 西塔台协调席 | C26: 0.62516204 | D26: 完成 | E26: 0.75704861 | F26: =(IF(E26-C26<0,"24:00"-C26+E26,E26-C26))*24 -> 3.1652778 | G26: =F26-H26 -> 3.1652778 | H26: =(IF(AND(C26>=$O$3,C26<$P$3,E26>=$O$3,E26<$P$3),E26-C26,IF(AND(C26>=$O$3,C26<$P$3,E26>=$P$3,E26<$N$3),$P$3-C26,IF(AND(C26>=$P$3,C26<$N$3,E26>=$O$3,E26<$P$3),E26,IF(AND(C26>=$P$3,C26<$N$3,E26>=$P$3,E26<$N$3),"0","none")))))*24 -> 0
A27: =IF(B27="","",IF(A27="",NOW(),A27)) -> 46228.715 | B27: 西塔台管制席 | C27: 0.87517361 | D27: 完成 | E27: 0.95875 | F27: =(IF(E27-C27<0,"24:00"-C27+E27,E27-C27))*24 -> 2.0058333 | G27: =F27-H27 -> 2.0058333 | H27: =(IF(AND(C27>=$O$3,C27<$P$3,E27>=$O$3,E27<$P$3),E27-C27,IF(AND(C27>=$O$3,C27<$P$3,E27>=$P$3,E27<$N$3),$P$3-C27,IF(AND(C27>=$P$3,C27<$N$3,E27>=$O$3,E27<$P$3),E27,IF(AND(C27>=$P$3,C27<$N$3,E27>=$P$3,E27<$N$3),"0","none")))))*24 -> 0
A28: =IF(B28="","",IF(A28="",NOW(),A28)) -> 46232.355 | B28: 带班主任 | C28: 0.35512731 | D28: 完成 | E28: 0.53405093 | F28: =(IF(E28-C28<0,"24:00"-C28+E28,E28-C28))*24 -> 4.2941667 | G28: =F28-H28 -> 4.2941667 | H28: =(IF(AND(C28>=$O$3,C28<$P$3,E28>=$O$3,E28<$P$3),E28-C28,IF(AND(C28>=$O$3,C28<$P$3,E28>=$P$3,E28<$N$3),$P$3-C28,IF(AND(C28>=$P$3,C28<$N$3,E28>=$O$3,E28<$P$3),E28,IF(AND(C28>=$P$3,C28<$N$3,E28>=$P$3,E28<$N$3),"0","none")))))*24 -> 0
A29: 46233 | B29: 带班主任 | C29: 0.77237269 | D29: 完成 | E29: 0.94494213 | F29: =(IF(E29-C29<0,"24:00"-C29+E29,E29-C29))*24 -> 4.1416667 | G29: =F29-H29 -> 4.1416667 | H29: =(IF(AND(C29>=$O$3,C29<$P$3,E29>=$O$3,E29<$P$3),E29-C29,IF(AND(C29>=$O$3,C29<$P$3,E29>=$P$3,E29<$N$3),$P$3-C29,IF(AND(C29>=$P$3,C29<$N$3,E29>=$O$3,E29<$P$3),E29,IF(AND(C29>=$P$3,C29<$N$3,E29>=$P$3,E29<$N$3),"0","none")))))*24 -> 0
A30: 46233 | B30: 带班主任 | C30: 0.29440972 | D30: 完成 | E30: 0.54174769 | F30: =(IF(E30-C30<0,"24:00"-C30+E30,E30-C30))*24 -> 5.9361111 | G30: =F30-H30 -> 5.0019444 | H30: =(IF(AND(C30>=$O$3,C30<$P$3,E30>=$O$3,E30<$P$3),E30-C30,IF(AND(C30>=$O$3,C30<$P$3,E30>=$P$3,E30<$N$3),$P$3-C30,IF(AND(C30>=$P$3,C30<$N$3,E30>=$O$3,E30<$P$3),E30,IF(AND(C30>=$P$3,C30<$N$3,E30>=$P$3,E30<$N$3),"0","none")))))*24 -> 0.93416667
A31: 46233 | B31: 带班主任 | C31: 0.93789352 | D31: 完成 | E31: 0.13938657 | F31: =(IF(E31-C31<0,"24:00"-C31+E31,E31-C31))*24 -> 4.8358333 | G31: =F31-H31 -> 1.4905556 | H31: =(IF(AND(C31>=$O$3,C31<$P$3,E31>=$O$3,E31<$P$3),E31-C31,IF(AND(C31>=$O$3,C31<$P$3,E31>=$P$3,E31<$N$3),$P$3-C31,IF(AND(C31>=$P$3,C31<$N$3,E31>=$O$3,E31<$P$3),E31,IF(AND(C31>=$P$3,C31<$N$3,E31>=$P$3,E31<$N$3),"0","none")))))*24 -> 3.3452778
A32: =IF(B32="","",IF(A32="",NOW(),A32)) | F32: =(IF(E32-C32<0,"24:00"-C32+E32,E32-C32))*24 -> 0 | G32: =F32-H32 -> 0 | H32: =(IF(AND(C32>=$O$3,C32<$P$3,E32>=$O$3,E32<$P$3),E32-C32,IF(AND(C32>=$O$3,C32<$P$3,E32>=$P$3,E32<$N$3),$P$3-C32,IF(AND(C32>=$P$3,C32<$N$3,E32>=$O$3,E32<$P$3),E32,IF(AND(C32>=$P$3,C32<$N$3,E32>=$P$3,E32<$N$3),"0","none")))))*24 -> 0
A33: =IF(B33="","",IF(A33="",NOW(),A33)) | F33: =(IF(E33-C33<0,"24:00"-C33+E33,E33-C33))*24 -> 0 | G33: =F33-H33 -> 0 | H33: =(IF(AND(C33>=$O$3,C33<$P$3,E33>=$O$3,E33<$P$3),E33-C33,IF(AND(C33>=$O$3,C33<$P$3,E33>=$P$3,E33<$N$3),$P$3-C33,IF(AND(C33>=$P$3,C33<$N$3,E33>=$O$3,E33<$P$3),E33,IF(AND(C33>=$P$3,C33<$N$3,E33>=$P$3,E33<$N$3),"0","none")))))*24 -> 0
A34: =IF(B34="","",IF(A34="",NOW(),A34)) | F34: =(IF(E34-C34<0,"24:00"-C34+E34,E34-C34))*24 -> 0 | G34: =F34-H34 -> 0 | H34: =(IF(AND(C34>=$O$3,C34<$P$3,E34>=$O$3,E34<$P$3),E34-C34,IF(AND(C34>=$O$3,C34<$P$3,E34>=$P$3,E34<$N$3),$P$3-C34,IF(AND(C34>=$P$3,C34<$N$3,E34>=$O$3,E34<$P$3),E34,IF(AND(C34>=$P$3,C34<$N$3,E34>=$P$3,E34<$N$3),"0","none")))))*24 -> 0
A35: =IF(B35="","",IF(A35="",NOW(),A35)) | F35: =(IF(E35-C35<0,"24:00"-C35+E35,E35-C35))*24 -> 0 | G35: =F35-H35 -> 0 | H35: =(IF(AND(C35>=$O$3,C35<$P$3,E35>=$O$3,E35<$P$3),E35-C35,IF(AND(C35>=$O$3,C35<$P$3,E35>=$P$3,E35<$N$3),$P$3-C35,IF(AND(C35>=$P$3,C35<$N$3,E35>=$O$3,E35<$P$3),E35,IF(AND(C35>=$P$3,C35<$N$3,E35>=$P$3,E35<$N$3),"0","none")))))*24 -> 0
A36: =IF(B36="","",IF(A36="",NOW(),A36)) | F36: =(IF(E36-C36<0,"24:00"-C36+E36,E36-C36))*24 -> 0 | G36: =F36-H36 -> 0 | H36: =(IF(AND(C36>=$O$3,C36<$P$3,E36>=$O$3,E36<$P$3),E36-C36,IF(AND(C36>=$O$3,C36<$P$3,E36>=$P$3,E36<$N$3),$P$3-C36,IF(AND(C36>=$P$3,C36<$N$3,E36>=$O$3,E36<$P$3),E36,IF(AND(C36>=$P$3,C36<$N$3,E36>=$P$3,E36<$N$3),"0","none")))))*24 -> 0
A37: =IF(B37="","",IF(A37="",NOW(),A37)) | F37: =(IF(E37-C37<0,"24:00"-C37+E37,E37-C37))*24 -> 0 | G37: =F37-H37 -> 0 | H37: =(IF(AND(C37>=$O$3,C37<$P$3,E37>=$O$3,E37<$P$3),E37-C37,IF(AND(C37>=$O$3,C37<$P$3,E37>=$P$3,E37<$N$3),$P$3-C37,IF(AND(C37>=$P$3,C37<$N$3,E37>=$O$3,E37<$P$3),E37,IF(AND(C37>=$P$3,C37<$N$3,E37>=$P$3,E37<$N$3),"0","none")))))*24 -> 0
A38: =IF(B38="","",IF(A38="",NOW(),A38)) | F38: =(IF(E38-C38<0,"24:00"-C38+E38,E38-C38))*24 -> 0 | G38: =F38-H38 -> 0 | H38: =(IF(AND(C38>=$O$3,C38<$P$3,E38>=$O$3,E38<$P$3),E38-C38,IF(AND(C38>=$O$3,C38<$P$3,E38>=$P$3,E38<$N$3),$P$3-C38,IF(AND(C38>=$P$3,C38<$N$3,E38>=$O$3,E38<$P$3),E38,IF(AND(C38>=$P$3,C38<$N$3,E38>=$P$3,E38<$N$3),"0","none")))))*24 -> 0
A39: =IF(B39="","",IF(A39="",NOW(),A39)) | F39: =(IF(E39-C39<0,"24:00"-C39+E39,E39-C39))*24 -> 0 | G39: =F39-H39 -> 0 | H39: =(IF(AND(C39>=$O$3,C39<$P$3,E39>=$O$3,E39<$P$3),E39-C39,IF(AND(C39>=$O$3,C39<$P$3,E39>=$P$3,E39<$N$3),$P$3-C39,IF(AND(C39>=$P$3,C39<$N$3,E39>=$O$3,E39<$P$3),E39,IF(AND(C39>=$P$3,C39<$N$3,E39>=$P$3,E39<$N$3),"0","none")))))*24 -> 0
A40: =IF(B40="","",IF(A40="",NOW(),A40)) | F40: =(IF(E40-C40<0,"24:00"-C40+E40,E40-C40))*24 -> 0 | G40: =F40-H40 -> 0 | H40: =(IF(AND(C40>=$O$3,C40<$P$3,E40>=$O$3,E40<$P$3),E40-C40,IF(AND(C40>=$O$3,C40<$P$3,E40>=$P$3,E40<$N$3),$P$3-C40,IF(AND(C40>=$P$3,C40<$N$3,E40>=$O$3,E40<$P$3),E40,IF(AND(C40>=$P$3,C40<$N$3,E40>=$P$3,E40<$N$3),"0","none")))))*24 -> 0
...

Sheet 明嘉
A1: 返回目录
A2: 日 期 | B2: 岗 位 | C2: 上岗时刻 | D2: 交接班 | E2: 离岗时刻 | F2: 时段工作小时 | G2: 白班小时 | H2: 夜班小时 (0200-0800) | I2: 统 计 | J2: 各席位总小时 | K2: 白班小时 | L2: 夜班小时 (0000-0800) | M2: 备注
A3: =IF(B3="","",IF(A3="",NOW(),A3)) -> 46204.358 | B3: 东塔台管制席 | C3: 0.35810185 | D3: 完成 | E3: 0.51427083 | F3: =(IF(E3-C3<0,"24:00"-C3+E3,E3-C3))*24 -> 3.7480556 | G3: =F3-H3 -> 3.7480556 | H3: =(IF(AND(C3>=$O$3,C3<$P$3,E3>=$O$3,E3<$P$3),E3-C3,IF(AND(C3>=$O$3,C3<$P$3,E3>=$P$3,E3<$N$3),$P$3-C3,IF(AND(C3>=$P$3,C3<$N$3,E3>=$O$3,E3<$P$3),E3,IF(AND(C3>=$P$3,C3<$N$3,E3>=$P$3,E3<$N$3),"0","none")))))*24 -> 0 | I3: 带班主任席执勤小时 | J3: =SUMIF(B:B,"带班主任",F:F) -> 0 | K3: =SUMIF(B:B,"带班主任",G:G) -> 0 | L3: =SUMIF(B:B,"带班主任",H:H) -> 0 | N3: 0.99998843 | O3: 0 | P3: 0.33333333
A4: =IF(B4="","",IF(A4="",NOW(),A4)) -> 46204.626 | B4: 东塔台协调席 | C4: 0.62627315 | D4: 完成 | E4: 0.76215278 | F4: =(IF(E4-C4<0,"24:00"-C4+E4,E4-C4))*24 -> 3.2611111 | G4: =F4-H4 -> 3.2611111 | H4: =(IF(AND(C4>=$O$3,C4<$P$3,E4>=$O$3,E4<$P$3),E4-C4,IF(AND(C4>=$O$3,C4<$P$3,E4>=$P$3,E4<$N$3),$P$3-C4,IF(AND(C4>=$P$3,C4<$N$3,E4>=$O$3,E4<$P$3),E4,IF(AND(C4>=$P$3,C4<$N$3,E4>=$P$3,E4<$N$3),"0","none")))))*24 -> 0 | I4: 机场管制席执勤小时 | J4: =SUMIF(B:B,"西塔台管制席",F:F)+SUMIF(B:B,"东塔台管制席",F:F) -> 29.812222 | K4: =SUMIF(B:B,"西塔台管制席",G:G)+SUMIF(B:B,"东塔台管制席",G:G) -> 19.035 | L4: =SUMIF(B:B,"西塔台管制席",H:H)+SUMIF(B:B,"东塔台管制席",H:H) -> 10.777222
A5: =IF(B5="","",IF(A5="",NOW(),A5)) -> 46204.877 | B5: 东塔台管制席 | C5: 0.87703704 | D5: 完成 | E5: 0.9552662 | F5: =(IF(E5-C5<0,"24:00"-C5+E5,E5-C5))*24 -> 1.8775 | G5: =F5-H5 -> 1.8775 | H5: =(IF(AND(C5>=$O$3,C5<$P$3,E5>=$O$3,E5<$P$3),E5-C5,IF(AND(C5>=$O$3,C5<$P$3,E5>=$P$3,E5<$N$3),$P$3-C5,IF(AND(C5>=$P$3,C5<$N$3,E5>=$O$3,E5<$P$3),E5,IF(AND(C5>=$P$3,C5<$N$3,E5>=$P$3,E5<$N$3),"0","none")))))*24 -> 0 | I5: 机场协调席执勤小时 | J5: =SUMIF(B:B,"西塔台协调席",F:F)+SUMIF(B:B,"东塔台协调席",F:F) -> 26.168333 | K5: =SUMIF(B:B,"西塔台协调席",G:G)+SUMIF(B:B,"东塔台协调席",G:G) -> 15.517778 | L5: =SUMIF(B:B,"西塔台协调席",H:H)+SUMIF(B:B,"东塔台协调席",H:H) -> 10.650556
A6: =IF(B6="","",IF(A6="",NOW(),A6)) -> 46205.299 | B6: 东塔台协调席 | C6: 0.29894676 | D6: 完成 | E6: 0.46393519 | F6: =(IF(E6-C6<0,"24:00"-C6+E6,E6-C6))*24 -> 3.9597222 | G6: =F6-H6 -> 3.1344444 | H6: =(IF(AND(C6>=$O$3,C6<$P$3,E6>=$O$3,E6<$P$3),E6-C6,IF(AND(C6>=$O$3,C6<$P$3,E6>=$P$3,E6<$N$3),$P$3-C6,IF(AND(C6>=$P$3,C6<$N$3,E6>=$O$3,E6<$P$3),E6,IF(AND(C6>=$P$3,C6<$N$3,E6>=$P$3,E6<$N$3),"0","none")))))*24 -> 0.82527778 | I6: 放行席执勤小时 | J6: =SUMIF(B:B,"放行席",F:F) -> 2.1491667 | K6: =SUMIF(B:B,"放行席",G:G) -> 0 | L6: =SUMIF(B:B,"放行席",H:H) -> 2.1491667
A7: =IF(B7="","",IF(A7="",NOW(),A7)) -> 46205.544 | B7: 东塔台管制席 | C7: 0.54375 | D7: 完成 | E7: 0.63232639 | F7: =(IF(E7-C7<0,"24:00"-C7+E7,E7-C7))*24 -> 2.1258333 | G7: =F7-H7 -> 2.1258333 | H7: =(IF(AND(C7>=$O$3,C7<$P$3,E7>=$O$3,E7<$P$3),E7-C7,IF(AND(C7>=$O$3,C7<$P$3,E7>=$P$3,E7<$N$3),$P$3-C7,IF(AND(C7>=$P$3,C7<$N$3,E7>=$O$3,E7<$P$3),E7,IF(AND(C7>=$P$3,C7<$N$3,E7>=$P$3,E7<$N$3),"0","none")))))*24 -> 0 | I7: 地面席执勤小时 | J7: =SUMIF(B:B,"地面席",F:F) -> 2.1952778 | K7: =SUMIF(B:B,"地面席",G:G) -> 0 | L7: =SUMIF(B:B,"地面席",H:H) -> 2.1952778
A8: =IF(B8="","",IF(A8="",NOW(),A8)) -> 46208.956 | B8: 西塔台协调席 | C8: 0.95569444 | D8: 完成 | E8: 0.095729167 | F8: =(IF(E8-C8<0,"24:00"-C8+E8,E8-C8))*24 -> 3.3608333 | G8: =F8-H8 -> 1.0633333 | H8: =(IF(AND(C8>=$O$3,C8<$P$3,E8>=$O$3,E8<$P$3),E8-C8,IF(AND(C8>=$O$3,C8<$P$3,E8>=$P$3,E8<$N$3),$P$3-C8,IF(AND(C8>=$P$3,C8<$N$3,E8>=$O$3,E8<$P$3),E8,IF(AND(C8>=$P$3,C8<$N$3,E8>=$P$3,E8<$N$3),"0","none")))))*24 -> 2.2975 | I8: 生产调度席执勤小时 | J8: =SUMIF(B:B,"生产调度席",F:F) -> 0 | K8: =SUMIF(B:B,"生产调度席",G:G) -> 0 | L8: =SUMIF(B:B,"生产调度席",H:H) -> 0
A9: =IF(B9="","",IF(A9="",NOW(),A9)) -> 46209.096 | B9: 东塔台协调席 | C9: 0.095833333 | D9: 完成 | E9: 0.1437037 | F9: =(IF(E9-C9<0,"24:00"-C9+E9,E9-C9))*24 -> 1.1488889 | G9: =F9-H9 -> 0 | H9: =(IF(AND(C9>=$O$3,C9<$P$3,E9>=$O$3,E9<$P$3),E9-C9,IF(AND(C9>=$O$3,C9<$P$3,E9>=$P$3,E9<$N$3),$P$3-C9,IF(AND(C9>=$P$3,C9<$N$3,E9>=$O$3,E9<$P$3),E9,IF(AND(C9>=$P$3,C9<$N$3,E9>=$P$3,E9<$N$3),"0","none")))))*24 -> 1.1488889 | I9: 航班调度席执勤小时 | J9: =SUMIF(B:B,"航班调度席",F:F) -> 6.4166667 | K9: =SUMIF(B:B,"航班调度席",G:G) -> 6.4166667 | L9: =SUMIF(B:B,"航班调度席",H:H) -> 0
A10: =IF(B10="","",IF(A10="",NOW(),A10)) -> 46210.014 | B10: 东塔台协调席 | C10: 0.01375 | D10: 完成 | E10: 0.14523148 | F10: =(IF(E10-C10<0,"24:00"-C10+E10,E10-C10))*24 -> 3.1555556 | G10: =F10-H10 -> 0 | H10: =(IF(AND(C10>=$O$3,C10<$P$3,E10>=$O$3,E10<$P$3),E10-C10,IF(AND(C10>=$O$3,C10<$P$3,E10>=$P$3,E10<$N$3),$P$3-C10,IF(AND(C10>=$P$3,C10<$N$3,E10>=$O$3,E10<$P$3),E10,IF(AND(C10>=$P$3,C10<$N$3,E10>=$P$3,E10<$N$3),"0","none")))))*24 -> 3.1555556 | I10: 综合协调席小时 | J10: =SUMIF(B:B,"综合协调席",F:F) -> 0 | K10: =SUMIF(B:B,"综合协调席",G:G) -> 0 | L10: =SUMIF(B:B,"综合协调席",H:H) -> 0
A11: =IF(B11="","",IF(A11="",NOW(),A11)) -> 46213.132 | B11: 放行席 | C11: 0.13240741 | D11: 完成 | E11: 0.22195602 | F11: =(IF(E11-C11<0,"24:00"-C11+E11,E11-C11))*24 -> 2.1491667 | G11: =F11-H11 -> 0 | H11: =(IF(AND(C11>=$O$3,C11<$P$3,E11>=$O$3,E11<$P$3),E11-C11,IF(AND(C11>=$O$3,C11<$P$3,E11>=$P$3,E11<$N$3),$P$3-C11,IF(AND(C11>=$P$3,C11<$N$3,E11>=$O$3,E11<$P$3),E11,IF(AND(C11>=$P$3,C11<$N$3,E11>=$P$3,E11<$N$3),"0","none")))))*24 -> 2.1491667 | I11: 见习管制员小时 | J11: =SUMIF(B:B,"见习管制员",F:F) -> 0 | K11: =SUMIF(B:B,"见习管制员",G:G) -> 0 | L11: =SUMIF(B:B,"见习管制员",H:H) -> 0
A12: =IF(B12="","",IF(A12="",NOW(),A12)) -> 46214.14 | B12: 西塔台管制席 | C12: 0.13986111 | D12: 完成 | E12: 0.25994213 | F12: =(IF(E12-C12<0,"24:00"-C12+E12,E12-C12))*24 -> 2.8819444 | G12: =F12-H12 -> 0 | H12: =(IF(AND(C12>=$O$3,C12<$P$3,E12>=$O$3,E12<$P$3),E12-C12,IF(AND(C12>=$O$3,C12<$P$3,E12>=$P$3,E12<$N$3),$P$3-C12,IF(AND(C12>=$P$3,C12<$N$3,E12>=$O$3,E12<$P$3),E12,IF(AND(C12>=$P$3,C12<$N$3,E12>=$P$3,E12<$N$3),"0","none")))))*24 -> 2.8819444 | I12: 管制教员席小时 | J12: =SUMIF(B:B,"管制教员席",F:F) -> 0 | K12: =SUMIF(B:B,"管制教员席",G:G) -> 0 | L12: =SUMIF(B:B,"管制教员席",H:H) -> 0
A13: =IF(B13="","",IF(A13="",NOW(),A13)) -> 46214.26 | B13: 东塔台协调席 | C13: 0.2600463 | D13: 完成 | E13: 0.30355324 | F13: =(IF(E13-C13<0,"24:00"-C13+E13,E13-C13))*24 -> 1.0441667 | G13: =F13-H13 -> 0 | H13: =(IF(AND(C13>=$O$3,C13<$P$3,E13>=$O$3,E13<$P$3),E13-C13,IF(AND(C13>=$O$3,C13<$P$3,E13>=$P$3,E13<$N$3),$P$3-C13,IF(AND(C13>=$P$3,C13<$N$3,E13>=$O$3,E13<$P$3),E13,IF(AND(C13>=$P$3,C13<$N$3,E13>=$P$3,E13<$N$3),"0","none")))))*24 -> 1.0441667 | I13: 月度总小时统计
A14: =IF(B14="","",IF(A14="",NOW(),A14)) -> 46216.504 | B14: 东塔台管制席 | C14: 0.50430556 | D14: 完成 | E14: 0.55613426 | F14: =(IF(E14-C14<0,"24:00"-C14+E14,E14-C14))*24 -> 1.2438889 | G14: =F14-H14 -> 1.2438889 | H14: =(IF(AND(C14>=$O$3,C14<$P$3,E14>=$O$3,E14<$P$3),E14-C14,IF(AND(C14>=$O$3,C14<$P$3,E14>=$P$3,E14<$N$3),$P$3-C14,IF(AND(C14>=$P$3,C14<$N$3,E14>=$O$3,E14<$P$3),E14,IF(AND(C14>=$P$3,C14<$N$3,E14>=$P$3,E14<$N$3),"0","none")))))*24 -> 0
A15: =IF(B15="","",IF(A15="",NOW(),A15)) -> 46216.568 | B15: 东塔台管制席 | C15: 0.5681713 | D15: 完成 | E15: 0.63121528 | F15: =(IF(E15-C15<0,"24:00"-C15+E15,E15-C15))*24 -> 1.5130556 | G15: =F15-H15 -> 1.5130556 | H15: =(IF(AND(C15>=$O$3,C15<$P$3,E15>=$O$3,E15<$P$3),E15-C15,IF(AND(C15>=$O$3,C15<$P$3,E15>=$P$3,E15<$N$3),$P$3-C15,IF(AND(C15>=$P$3,C15<$N$3,E15>=$O$3,E15<$P$3),E15,IF(AND(C15>=$P$3,C15<$N$3,E15>=$P$3,E15<$N$3),"0","none")))))*24 -> 0 | I15: 统计 | J15: 各席位总小时 | K15: 白班小时 | L15: 夜班小时 (0000-0800) | M15: 备注
A16: =IF(B16="","",IF(A16="",NOW(),A16)) -> 46216.753 | B16: 东塔台协调席 | C16: 0.75265046 | D16: 完成 | E16: 0.88005787 | F16: =(IF(E16-C16<0,"24:00"-C16+E16,E16-C16))*24 -> 3.0577778 | G16: =F16-H16 -> 3.0577778 | H16: =(IF(AND(C16>=$O$3,C16<$P$3,E16>=$O$3,E16<$P$3),E16-C16,IF(AND(C16>=$O$3,C16<$P$3,E16>=$P$3,E16<$N$3),$P$3-C16,IF(AND(C16>=$P$3,C16<$N$3,E16>=$O$3,E16<$P$3),E16,IF(AND(C16>=$P$3,C16<$N$3,E16>=$P$3,E16<$N$3),"0","none")))))*24 -> 0 | I16: 带班主任席执勤小时 | J16: =J3 -> 0 | K16: =K3 -> 0 | L16: =L3 -> 0
A17: =IF(B17="","",IF(A17="",NOW(),A17)) -> 46217.299 | B17: 西塔台管制席 | C17: 0.29892361 | D17: 完成 | E17: 0.46777778 | F17: =(IF(E17-C17<0,"24:00"-C17+E17,E17-C17))*24 -> 4.0525 | G17: =F17-H17 -> 3.2266667 | H17: =(IF(AND(C17>=$O$3,C17<$P$3,E17>=$O$3,E17<$P$3),E17-C17,IF(AND(C17>=$O$3,C17<$P$3,E17>=$P$3,E17<$N$3),$P$3-C17,IF(AND(C17>=$P$3,C17<$N$3,E17>=$O$3,E17<$P$3),E17,IF(AND(C17>=$P$3,C17<$N$3,E17>=$P$3,E17<$N$3),"0","none")))))*24 -> 0.82583333 | I17: 席位执勤小时 | J17: =J4+J5+J6+J7+J10 -> 60.325 | K17: =K4+K5+K6+K7+K10 -> 34.552778 | L17: =L4+L5+L6+L7+L10 -> 25.772222
A18: =IF(B18="","",IF(A18="",NOW(),A18)) -> 46217.542 | B18: 西塔台管制席 | C18: 0.54210648 | D18: 完成 | E18: 0.63165509 | F18: =(IF(E18-C18<0,"24:00"-C18+E18,E18-C18))*24 -> 2.1491667 | G18: =F18-H18 -> 2.1491667 | H18: =(IF(AND(C18>=$O$3,C18<$P$3,E18>=$O$3,E18<$P$3),E18-C18,IF(AND(C18>=$O$3,C18<$P$3,E18>=$P$3,E18<$N$3),$P$3-C18,IF(AND(C18>=$P$3,C18<$N$3,E18>=$O$3,E18<$P$3),E18,IF(AND(C18>=$P$3,C18<$N$3,E18>=$P$3,E18<$N$3),"0","none")))))*24 -> 0 | I18: 见习管制员小时 | J18: =J11 -> 0 | K18: =K11 -> 0 | L18: =L11 -> 0
A19: =IF(B19="","",IF(A19="",NOW(),A19)) -> 46221.013 | B19: 西塔台管制席 | C19: 0.013449074 | D19: 完成 | E19: 0.14416667 | F19: =(IF(E19-C19<0,"24:00"-C19+E19,E19-C19))*24 -> 3.1372222 | G19: =F19-H19 -> 0 | H19: =(IF(AND(C19>=$O$3,C19<$P$3,E19>=$O$3,E19<$P$3),E19-C19,IF(AND(C19>=$O$3,C19<$P$3,E19>=$P$3,E19<$N$3),$P$3-C19,IF(AND(C19>=$P$3,C19<$N$3,E19>=$O$3,E19<$P$3),E19,IF(AND(C19>=$P$3,C19<$N$3,E19>=$P$3,E19<$N$3),"0","none")))))*24 -> 3.1372222 | I19: 管制教员小时 | J19: =J12 -> 0 | K19: =K12 -> 0 | L19: =L12 -> 0
A20: =IF(B20="","",IF(A20="",NOW(),A20)) -> 46225.139 | B20: 东塔台管制席 | C20: 0.1394213 | D20: 完成 | E20: 0.30326389 | F20: =(IF(E20-C20<0,"24:00"-C20+E20,E20-C20))*24 -> 3.9322222 | G20: =F20-H20 -> 0 | H20: =(IF(AND(C20>=$O$3,C20<$P$3,E20>=$O$3,E20<$P$3),E20-C20,IF(AND(C20>=$O$3,C20<$P$3,E20>=$P$3,E20<$N$3),$P$3-C20,IF(AND(C20>=$P$3,C20<$N$3,E20>=$O$3,E20<$P$3),E20,IF(AND(C20>=$P$3,C20<$N$3,E20>=$P$3,E20<$N$3),"0","none")))))*24 -> 3.9322222 | I20: 月度总小时 | J20: =J16+J17+J18+J19 -> 60.325
A21: =IF(B21="","",IF(A21="",NOW(),A21)) -> 46226.139 | B21: 地面席 | C21: 0.13900463 | D21: 完成 | E21: 0.23047454 | F21: =(IF(E21-C21<0,"24:00"-C21+E21,E21-C21))*24 -> 2.1952778 | G21: =F21-H21 -> 0 | H21: =(IF(AND(C21>=$O$3,C21<$P$3,E21>=$O$3,E21<$P$3),E21-C21,IF(AND(C21>=$O$3,C21<$P$3,E21>=$P$3,E21<$N$3),$P$3-C21,IF(AND(C21>=$P$3,C21<$N$3,E21>=$O$3,E21<$P$3),E21,IF(AND(C21>=$P$3,C21<$N$3,E21>=$P$3,E21<$N$3),"0","none")))))*24 -> 2.1952778 | I21: 调度席 | J21: =SUM(J8:J9) -> 6.4166667 | K21: =SUM(K8:K9) -> 6.4166667 | L21: =SUM(L8:L9) -> 0
A22: =IF(B22="","",IF(A22="",NOW(),A22)) -> 46228.378 | B22: 航班调度席 | C22: 0.3781713 | D22: 完成 | E22: 0.53175926 | F22: =(IF(E22-C22<0,"24:00"-C22+E22,E22-C22))*24 -> 3.6861111 | G22: =F22-H22 -> 3.6861111 | H22: =(IF(AND(C22>=$O$3,C22<$P$3,E22>=$O$3,E22<$P$3),E22-C22,IF(AND(C22>=$O$3,C22<$P$3,E22>=$P$3,E22<$N$3),$P$3-C22,IF(AND(C22>=$P$3,C22<$N$3,E22>=$O$3,E22<$P$3),E22,IF(AND(C22>=$P$3,C22<$N$3,E22>=$P$3,E22<$N$3),"0","none")))))*24 -> 0
A23: =IF(B23="","",IF(A23="",NOW(),A23)) -> 46228.616 | B23: 航班调度席 | C23: 0.61550926 | D23: 完成 | E23: 0.72928241 | F23: =(IF(E23-C23<0,"24:00"-C23+E23,E23-C23))*24 -> 2.7305556 | G23: =F23-H23 -> 2.7305556 | H23: =(IF(AND(C23>=$O$3,C23<$P$3,E23>=$O$3,E23<$P$3),E23-C23,IF(AND(C23>=$O$3,C23<$P$3,E23>=$P$3,E23<$N$3),$P$3-C23,IF(AND(C23>=$P$3,C23<$N$3,E23>=$O$3,E23<$P$3),E23,IF(AND(C23>=$P$3,C23<$N$3,E23>=$P$3,E23<$N$3),"0","none")))))*24 -> 0
A24: =IF(B24="","",IF(A24="",NOW(),A24)) -> 46229.015 | B24: 东塔台协调席 | C24: 0.014756944 | D24: 完成 | E24: 0.10555556 | F24: =(IF(E24-C24<0,"24:00"-C24+E24,E24-C24))*24 -> 2.1791667 | G24: =F24-H24 -> 0 | H24: =(IF(AND(C24>=$O$3,C24<$P$3,E24>=$O$3,E24<$P$3),E24-C24,IF(AND(C24>=$O$3,C24<$P$3,E24>=$P$3,E24<$N$3),$P$3-C24,IF(AND(C24>=$P$3,C24<$N$3,E24>=$O$3,E24<$P$3),E24,IF(AND(C24>=$P$3,C24<$N$3,E24>=$P$3,E24<$N$3),"0","none")))))*24 -> 2.1791667
A25: =IF(B25="","",IF(A25="",NOW(),A25)) -> 46229.459 | B25: 东塔台协调席 | C25: 0.45929398 | D25: 完成 | E25: 0.54636574 | F25: =(IF(E25-C25<0,"24:00"-C25+E25,E25-C25))*24 -> 2.0897222 | G25: =F25-H25 -> 2.0897222 | H25: =(IF(AND(C25>=$O$3,C25<$P$3,E25>=$O$3,E25<$P$3),E25-C25,IF(AND(C25>=$O$3,C25<$P$3,E25>=$P$3,E25<$N$3),$P$3-C25,IF(AND(C25>=$P$3,C25<$N$3,E25>=$O$3,E25<$P$3),E25,IF(AND(C25>=$P$3,C25<$N$3,E25>=$P$3,E25<$N$3),"0","none")))))*24 -> 0
A26: =IF(B26="","",IF(A26="",NOW(),A26)) -> 46229.624 | B26: 东塔台管制席 | C26: 0.62377315 | D26: 完成 | E26: 0.75505787 | F26: =(IF(E26-C26<0,"24:00"-C26+E26,E26-C26))*24 -> 3.1508333 | G26: =F26-H26 -> 3.1508333 | H26: =(IF(AND(C26>=$O$3,C26<$P$3,E26>=$O$3,E26<$P$3),E26-C26,IF(AND(C26>=$O$3,C26<$P$3,E26>=$P$3,E26<$N$3),$P$3-C26,IF(AND(C26>=$P$3,C26<$N$3,E26>=$O$3,E26<$P$3),E26,IF(AND(C26>=$P$3,C26<$N$3,E26>=$P$3,E26<$N$3),"0","none")))))*24 -> 0
A27: =IF(B27="","",IF(A27="",NOW(),A27)) -> 46229.835 | B27: 东塔台协调席 | C27: 0.83471065 | D27: 完成 | E27: 0.95601852 | F27: =(IF(E27-C27<0,"24:00"-C27+E27,E27-C27))*24 -> 2.9113889 | G27: =F27-H27 -> 2.9113889 | H27: =(IF(AND(C27>=$O$3,C27<$P$3,E27>=$O$3,E27<$P$3),E27-C27,IF(AND(C27>=$O$3,C27<$P$3,E27>=$P$3,E27<$N$3),$P$3-C27,IF(AND(C27>=$P$3,C27<$N$3,E27>=$O$3,E27<$P$3),E27,IF(AND(C27>=$P$3,C27<$N$3,E27>=$P$3,E27<$N$3),"0","none")))))*24 -> 0
A28: =IF(B28="","",IF(A28="",NOW(),A28)) | F28: =(IF(E28-C28<0,"24:00"-C28+E28,E28-C28))*24 -> 0 | G28: =F28-H28 -> 0 | H28: =(IF(AND(C28>=$O$3,C28<$P$3,E28>=$O$3,E28<$P$3),E28-C28,IF(AND(C28>=$O$3,C28<$P$3,E28>=$P$3,E28<$N$3),$P$3-C28,IF(AND(C28>=$P$3,C28<$N$3,E28>=$O$3,E28<$P$3),E28,IF(AND(C28>=$P$3,C28<$N$3,E28>=$P$3,E28<$N$3),"0","none")))))*24 -> 0
A29: =IF(B29="","",IF(A29="",NOW(),A29)) | F29: =(IF(E29-C29<0,"24:00"-C29+E29,E29-C29))*24 -> 0 | G29: =F29-H29 -> 0 | H29: =(IF(AND(C29>=$O$3,C29<$P$3,E29>=$O$3,E29<$P$3),E29-C29,IF(AND(C29>=$O$3,C29<$P$3,E29>=$P$3,E29<$N$3),$P$3-C29,IF(AND(C29>=$P$3,C29<$N$3,E29>=$O$3,E29<$P$3),E29,IF(AND(C29>=$P$3,C29<$N$3,E29>=$P$3,E29<$N$3),"0","none")))))*24 -> 0
A30: =IF(B30="","",IF(A30="",NOW(),A30)) | F30: =(IF(E30-C30<0,"24:00"-C30+E30,E30-C30))*24 -> 0 | G30: =F30-H30 -> 0 | H30: =(IF(AND(C30>=$O$3,C30<$P$3,E30>=$O$3,E30<$P$3),E30-C30,IF(AND(C30>=$O$3,C30<$P$3,E30>=$P$3,E30<$N$3),$P$3-C30,IF(AND(C30>=$P$3,C30<$N$3,E30>=$O$3,E30<$P$3),E30,IF(AND(C30>=$P$3,C30<$N$3,E30>=$P$3,E30<$N$3),"0","none")))))*24 -> 0
A31: =IF(B31="","",IF(A31="",NOW(),A31)) | F31: =(IF(E31-C31<0,"24:00"-C31+E31,E31-C31))*24 -> 0 | G31: =F31-H31 -> 0 | H31: =(IF(AND(C31>=$O$3,C31<$P$3,E31>=$O$3,E31<$P$3),E31-C31,IF(AND(C31>=$O$3,C31<$P$3,E31>=$P$3,E31<$N$3),$P$3-C31,IF(AND(C31>=$P$3,C31<$N$3,E31>=$O$3,E31<$P$3),E31,IF(AND(C31>=$P$3,C31<$N$3,E31>=$P$3,E31<$N$3),"0","none")))))*24 -> 0
A32: =IF(B32="","",IF(A32="",NOW(),A32)) | F32: =(IF(E32-C32<0,"24:00"-C32+E32,E32-C32))*24 -> 0 | G32: =F32-H32 -> 0 | H32: =(IF(AND(C32>=$O$3,C32<$P$3,E32>=$O$3,E32<$P$3),E32-C32,IF(AND(C32>=$O$3,C32<$P$3,E32>=$P$3,E32<$N$3),$P$3-C32,IF(AND(C32>=$P$3,C32<$N$3,E32>=$O$3,E32<$P$3),E32,IF(AND(C32>=$P$3,C32<$N$3,E32>=$P$3,E32<$N$3),"0","none")))))*24 -> 0
A33: =IF(B33="","",IF(A33="",NOW(),A33)) | F33: =(IF(E33-C33<0,"24:00"-C33+E33,E33-C33))*24 -> 0 | G33: =F33-H33 -> 0 | H33: =(IF(AND(C33>=$O$3,C33<$P$3,E33>=$O$3,E33<$P$3),E33-C33,IF(AND(C33>=$O$3,C33<$P$3,E33>=$P$3,E33<$N$3),$P$3-C33,IF(AND(C33>=$P$3,C33<$N$3,E33>=$O$3,E33<$P$3),E33,IF(AND(C33>=$P$3,C33<$N$3,E33>=$P$3,E33<$N$3),"0","none")))))*24 -> 0
A34: =IF(B34="","",IF(A34="",NOW(),A34)) | F34: =(IF(E34-C34<0,"24:00"-C34+E34,E34-C34))*24 -> 0 | G34: =F34-H34 -> 0 | H34: =(IF(AND(C34>=$O$3,C34<$P$3,E34>=$O$3,E34<$P$3),E34-C34,IF(AND(C34>=$O$3,C34<$P$3,E34>=$P$3,E34<$N$3),$P$3-C34,IF(AND(C34>=$P$3,C34<$N$3,E34>=$O$3,E34<$P$3),E34,IF(AND(C34>=$P$3,C34<$N$3,E34>=$P$3,E34<$N$3),"0","none")))))*24 -> 0
A35: =IF(B35="","",IF(A35="",NOW(),A35)) | F35: =(IF(E35-C35<0,"24:00"-C35+E35,E35-C35))*24 -> 0 | G35: =F35-H35 -> 0 | H35: =(IF(AND(C35>=$O$3,C35<$P$3,E35>=$O$3,E35<$P$3),E35-C35,IF(AND(C35>=$O$3,C35<$P$3,E35>=$P$3,E35<$N$3),$P$3-C35,IF(AND(C35>=$P$3,C35<$N$3,E35>=$O$3,E35<$P$3),E35,IF(AND(C35>=$P$3,C35<$N$3,E35>=$P$3,E35<$N$3),"0","none")))))*24 -> 0
A36: =IF(B36="","",IF(A36="",NOW(),A36)) | F36: =(IF(E36-C36<0,"24:00"-C36+E36,E36-C36))*24 -> 0 | G36: =F36-H36 -> 0 | H36: =(IF(AND(C36>=$O$3,C36<$P$3,E36>=$O$3,E36<$P$3),E36-C36,IF(AND(C36>=$O$3,C36<$P$3,E36>=$P$3,E36<$N$3),$P$3-C36,IF(AND(C36>=$P$3,C36<$N$3,E36>=$O$3,E36<$P$3),E36,IF(AND(C36>=$P$3,C36<$N$3,E36>=$P$3,E36<$N$3),"0","none")))))*24 -> 0
A37: =IF(B37="","",IF(A37="",NOW(),A37)) | F37: =(IF(E37-C37<0,"24:00"-C37+E37,E37-C37))*24 -> 0 | G37: =F37-H37 -> 0 | H37: =(IF(AND(C37>=$O$3,C37<$P$3,E37>=$O$3,E37<$P$3),E37-C37,IF(AND(C37>=$O$3,C37<$P$3,E37>=$P$3,E37<$N$3),$P$3-C37,IF(AND(C37>=$P$3,C37<$N$3,E37>=$O$3,E37<$P$3),E37,IF(AND(C37>=$P$3,C37<$N$3,E37>=$P$3,E37<$N$3),"0","none")))))*24 -> 0
A38: =IF(B38="","",IF(A38="",NOW(),A38)) | F38: =(IF(E38-C38<0,"24:00"-C38+E38,E38-C38))*24 -> 0 | G38: =F38-H38 -> 0 | H38: =(IF(AND(C38>=$O$3,C38<$P$3,E38>=$O$3,E38<$P$3),E38-C38,IF(AND(C38>=$O$3,C38<$P$3,E38>=$P$3,E38<$N$3),$P$3-C38,IF(AND(C38>=$P$3,C38<$N$3,E38>=$O$3,E38<$P$3),E38,IF(AND(C38>=$P$3,C38<$N$3,E38>=$P$3,E38<$N$3),"0","none")))))*24 -> 0
A39: =IF(B39="","",IF(A39="",NOW(),A39)) | F39: =(IF(E39-C39<0,"24:00"-C39+E39,E39-C39))*24 -> 0 | G39: =F39-H39 -> 0 | H39: =(IF(AND(C39>=$O$3,C39<$P$3,E39>=$O$3,E39<$P$3),E39-C39,IF(AND(C39>=$O$3,C39<$P$3,E39>=$P$3,E39<$N$3),$P$3-C39,IF(AND(C39>=$P$3,C39<$N$3,E39>=$O$3,E39<$P$3),E39,IF(AND(C39>=$P$3,C39<$N$3,E39>=$P$3,E39<$N$3),"0","none")))))*24 -> 0
... A160: =IF(B160="","",IF(A160="",NOW(),A160)) | F160: =(IF(E160-C160<0,"24:00"-C160+E160,E160-C160))*24 -> 0 | G160: =F160-H160 -> 0 | H160: =(IF(AND(C160>=$O$3,C160<$P$3,E160>=$O$3,E160<$P$3),E160-C160,IF(AND(C160>=$O$3,C160<$P$3,E160>=$P$3,E160<$N$3),$P$3-C160,IF(AND(C160>=$P$3,C160<$N$3,E160>=$O$3,E160<$P$3),E160,IF(AND(C160>=$P$3,C160<$N$3,E160>=$P$3,E160<$N$3),"0","none")))))*24 -> 0
...

Sheet 徐万友
A1: 返回目录
A2: 日 期 | B2: 岗 位 | C2: 上岗时刻 | D2: 交接班 | E2: 离岗时刻 | F2: 时段工作小时 | G2: 白班小时 | H2: 夜班小时 (0200-0800) | I2: 统 计 | J2: 各席位总小时 | K2: 白班小时 | L2: 夜班小时 (0000-0800) | M2: 备注
A3: =IF(B3="","",IF(A3="",NOW(),A3)) -> 46204.358 | B3: 带班主任 | C3: 0.35790509 | D3: 完成 | E3: 0.53399306 | F3: =(IF(E3-C3<0,"24:00"-C3+E3,E3-C3))*24 -> 4.2261111 | G3: =F3-H3 -> 4.2261111 | H3: =(IF(AND(C3>=$O$3,C3<$P$3,E3>=$O$3,E3<$P$3),E3-C3,IF(AND(C3>=$O$3,C3<$P$3,E3>=$P$3,E3<$N$3),$P$3-C3,IF(AND(C3>=$P$3,C3<$N$3,E3>=$O$3,E3<$P$3),E3,IF(AND(C3>=$P$3,C3<$N$3,E3>=$P$3,E3<$N$3),"0","none")))))*24 -> 0 | I3: 带班主任席执勤小时 | J3: =SUMIF(B:B,"带班主任",F:F) -> 87.653056 | K3: =SUMIF(B:B,"带班主任",G:G) -> 69.830556 | L3: =SUMIF(B:B,"带班主任",H:H) -> 17.8225 | N3: 0.99998843 | O3: 0 | P3: 0.33333333
A4: =IF(B4="","",IF(A4="",NOW(),A4)) -> 46204.645 | B4: 带班主任 | C4: 0.64517361 | D4: 完成 | E4: 0.78641204 | F4: =(IF(E4-C4<0,"24:00"-C4+E4,E4-C4))*24 -> 3.3897222 | G4: =F4-H4 -> 3.3897222 | H4: =(IF(AND(C4>=$O$3,C4<$P$3,E4>=$O$3,E4<$P$3),E4-C4,IF(AND(C4>=$O$3,C4<$P$3,E4>=$P$3,E4<$N$3),$P$3-C4,IF(AND(C4>=$P$3,C4<$N$3,E4>=$O$3,E4<$P$3),E4,IF(AND(C4>=$P$3,C4<$N$3,E4>=$P$3,E4<$N$3),"0","none")))))*24 -> 0 | I4: 机场管制席执勤小时 | J4: =SUMIF(B:B,"西塔台管制席",F:F)+SUMIF(B:B,"东塔台管制席",F:F) -> 4.6675 | K4: =SUMIF(B:B,"西塔台管制席",G:G)+SUMIF(B:B,"东塔台管制席",G:G) -> 1.1502778 | L4: =SUMIF(B:B,"西塔台管制席",H:H)+SUMIF(B:B,"东塔台管制席",H:H) -> 3.5172222
A5: =IF(B5="","",IF(A5="",NOW(),A5)) -> 46205.519 | B5: 带班主任 | C5: 0.51892361 | D5: 完成 | E5: 0.66055556 | F5: =(IF(E5-C5<0,"24:00"-C5+E5,E5-C5))*24 -> 3.3991667 | G5: =F5-H5 -> 3.3991667 | H5: =(IF(AND(C5>=$O$3,C5<$P$3,E5>=$O$3,E5<$P$3),E5-C5,IF(AND(C5>=$O$3,C5<$P$3,E5>=$P$3,E5<$N$3),$P$3-C5,IF(AND(C5>=$P$3,C5<$N$3,E5>=$O$3,E5<$P$3),E5,IF(AND(C5>=$P$3,C5<$N$3,E5>=$P$3,E5<$N$3),"0","none")))))*24 -> 0 | I5: 机场协调席执勤小时 | J5: =SUMIF(B:B,"西塔台协调席",F:F)+SUMIF(B:B,"东塔台协调席",F:F) -> 0 | K5: =SUMIF(B:B,"西塔台协调席",G:G)+SUMIF(B:B,"东塔台协调席",G:G) -> 0 | L5: =SUMIF(B:B,"西塔台协调席",H:H)+SUMIF(B:B,"东塔台协调席",H:H) -> 0
A6: =IF(B6="","",IF(A6="",NOW(),A6)) -> 46205.771 | B6: 带班主任 | C6: 0.77092593 | D6: 完成 | E6: 0.95509259 | F6: =(IF(E6-C6<0,"24:00"-C6+E6,E6-C6))*24 -> 4.42 | G6: =F6-H6 -> 4.42 | H6: =(IF(AND(C6>=$O$3,C6<$P$3,E6>=$O$3,E6<$P$3),E6-C6,IF(AND(C6>=$O$3,C6<$P$3,E6>=$P$3,E6<$N$3),$P$3-C6,IF(AND(C6>=$P$3,C6<$N$3,E6>=$O$3,E6<$P$3),E6,IF(AND(C6>=$P$3,C6<$N$3,E6>=$P$3,E6<$N$3),"0","none")))))*24 -> 0 | I6: 放行席执勤小时 | J6: =SUMIF(B:B,"放行席",F:F) -> 0 | K6: =SUMIF(B:B,"放行席",G:G) -> 0 | L6: =SUMIF(B:B,"放行席",H:H) -> 0
A7: =IF(B7="","",IF(A7="",NOW(),A7)) -> 46206.29 | B7: 带班主任 | C7: 0.2900463 | D7: 完成 | E7: 0.36576389 | F7: =(IF(E7-C7<0,"24:00"-C7+E7,E7-C7))*24 -> 1.8172222 | G7: =F7-H7 -> 0.77833333 | H7: =(IF(AND(C7>=$O$3,C7<$P$3,E7>=$O$3,E7<$P$3),E7-C7,IF(AND(C7>=$O$3,C7<$P$3,E7>=$P$3,E7<$N$3),$P$3-C7,IF(AND(C7>=$P$3,C7<$N$3,E7>=$O$3,E7<$P$3),E7,IF(AND(C7>=$P$3,C7<$N$3,E7>=$P$3,E7<$N$3),"0","none")))))*24 -> 1.0388889 | I7: 地面席执勤小时 | J7: =SUMIF(B:B,"地面席",F:F) -> 0 | K7: =SUMIF(B:B,"地面席",G:G) -> 0 | L7: =SUMIF(B:B,"地面席",H:H) -> 0
A8: =IF(B8="","",IF(A8="",NOW(),A8)) -> 46208.524 | B8: 带班主任 | C8: 0.52395833 | D8: 完成 | E8: 0.64454861 | F8: =(IF(E8-C8<0,"24:00"-C8+E8,E8-C8))*24 -> 2.8941667 | G8: =F8-H8 -> 2.8941667 | H8: =(IF(AND(C8>=$O$3,C8<$P$3,E8>=$O$3,E8<$P$3),E8-C8,IF(AND(C8>=$O$3,C8<$P$3,E8>=$P$3,E8<$N$3),$P$3-C8,IF(AND(C8>=$P$3,C8<$N$3,E8>=$O$3,E8<$P$3),E8,IF(AND(C8>=$P$3,C8<$N$3,E8>=$P$3,E8<$N$3),"0","none")))))*24 -> 0 | I8: 生产调度席执勤小时 | J8: =SUMIF(B:B,"生产调度席",F:F) -> 0 | K8: =SUMIF(B:B,"生产调度席",G:G) -> 0 | L8: =SUMIF(B:B,"生产调度席",H:H) -> 0
A9: =IF(B9="","",IF(A9="",NOW(),A9)) -> 46208.77 | B9: 带班主任 | C9: 0.76949074 | D9: 完成 | E9: 0.9496875 | F9: =(IF(E9-C9<0,"24:00"-C9+E9,E9-C9))*24 -> 4.3247222 | G9: =F9-H9 -> 4.3247222 | H9: =(IF(AND(C9>=$O$3,C9<$P$3,E9>=$O$3,E9<$P$3),E9-C9,IF(AND(C9>=$O$3,C9<$P$3,E9>=$P$3,E9<$N$3),$P$3-C9,IF(AND(C9>=$P$3,C9<$N$3,E9>=$O$3,E9<$P$3),E9,IF(AND(C9>=$P$3,C9<$N$3,E9>=$P$3,E9<$N$3),"0","none")))))*24 -> 0 | I9: 航班调度席执勤小时 | J9: =SUMIF(B:B,"航班调度席",F:F) -> 0 | K9: =SUMIF(B:B,"航班调度席",G:G) -> 0 | L9: =SUMIF(B:B,"航班调度席",H:H) -> 0
A10: =IF(B10="","",IF(A10="",NOW(),A10)) -> 46217.132 | B10: 带班主任 | C10: 0.13190972 | D10: 完成 | E10: 0.30048611 | F10: =(IF(E10-C10<0,"24:00"-C10+E10,E10-C10))*24 -> 4.0458333 | G10: =F10-H10 -> 0 | H10: =(IF(AND(C10>=$O$3,C10<$P$3,E10>=$O$3,E10<$P$3),E10-C10,IF(AND(C10>=$O$3,C10<$P$3,E10>=$P$3,E10<$N$3),$P$3-C10,IF(AND(C10>=$P$3,C10<$N$3,E10>=$O$3,E10<$P$3),E10,IF(AND(C10>=$P$3,C10<$N$3,E10>=$P$3,E10<$N$3),"0","none")))))*24 -> 4.0458333 | I10: 综合协调席小时 | J10: =SUMIF(B:B,"综合协调席",F:F) -> 0 | K10: =SUMIF(B:B,"综合协调席",G:G) -> 0 | L10: =SUMIF(B:B,"综合协调席",H:H) -> 0
A11: =IF(B11="","",IF(A11="",NOW(),A11)) -> 46217.938 | B11: 带班主任 | C11: 0.93841435 | D11: 完成 | E11: 0.13730324 | F11: =(IF(E11-C11<0,"24:00"-C11+E11,E11-C11))*24 -> 4.7733333 | G11: =F11-H11 -> 1.4780556 | H11: =(IF(AND(C11>=$O$3,C11<$P$3,E11>=$O$3,E11<$P$3),E11-C11,IF(AND(C11>=$O$3,C11<$P$3,E11>=$P$3,E11<$N$3),$P$3-C11,IF(AND(C11>=$P$3,C11<$N$3,E11>=$O$3,E11<$P$3),E11,IF(AND(C11>=$P$3,C11<$N$3,E11>=$P$3,E11<$N$3),"0","none")))))*24 -> 3.2952778 | I11: 见习管制员小时 | J11: =SUMIF(B:B,"见习管制员",F:F) -> 0 | K11: =SUMIF(B:B,"见习管制员",G:G) -> 0 | L11: =SUMIF(B:B,"见习管制员",H:H) -> 0
A12: =IF(B12="","",IF(A12="",NOW(),A12)) -> 46220.524 | B12: 带班主任 | C12: 0.52381944 | D12: 完成 | E12: 0.65354167 | F12: =(IF(E12-C12<0,"24:00"-C12+E12,E12-C12))*24 -> 3.1133333 | G12: =F12-H12 -> 3.1133333 | H12: =(IF(AND(C12>=$O$3,C12<$P$3,E12>=$O$3,E12<$P$3),E12-C12,IF(AND(C12>=$O$3,C12<$P$3,E12>=$P$3,E12<$N$3),$P$3-C12,IF(AND(C12>=$P$3,C12<$N$3,E12>=$O$3,E12<$P$3),E12,IF(AND(C12>=$P$3,C12<$N$3,E12>=$P$3,E12<$N$3),"0","none")))))*24 -> 0 | I12: 管制教员席小时 | J12: =SUMIF(B:B,"管制教员席",F:F) -> 0 | K12: =SUMIF(B:B,"管制教员席",G:G) -> 0 | L12: =SUMIF(B:B,"管制教员席",H:H) -> 0
A13: =IF(B13="","",IF(A13="",NOW(),A13)) -> 46220.815 | B13: 带班主任 | C13: 0.81483796 | D13: 完成 | E13: 0.94525463 | F13: =(IF(E13-C13<0,"24:00"-C13+E13,E13-C13))*24 -> 3.13 | G13: =F13-H13 -> 3.13 | H13: =(IF(AND(C13>=$O$3,C13<$P$3,E13>=$O$3,E13<$P$3),E13-C13,IF(AND(C13>=$O$3,C13<$P$3,E13>=$P$3,E13<$N$3),$P$3-C13,IF(AND(C13>=$P$3,C13<$N$3,E13>=$O$3,E13<$P$3),E13,IF(AND(C13>=$P$3,C13<$N$3,E13>=$P$3,E13<$N$3),"0","none")))))*24 -> 0 | I13: 月度总小时统计
A14: =IF(B14="","",IF(A14="",NOW(),A14)) -> 46221.3 | B14: 带班主任 | C14: 0.30032407 | D14: 完成 | E14: 0.54788194 | F14: =(IF(E14-C14<0,"24:00"-C14+E14,E14-C14))*24 -> 5.9413889 | G14: =F14-H14 -> 5.1491667 | H14: =(IF(AND(C14>=$O$3,C14<$P$3,E14>=$O$3,E14<$P$3),E14-C14,IF(AND(C14>=$O$3,C14<$P$3,E14>=$P$3,E14<$N$3),$P$3-C14,IF(AND(C14>=$P$3,C14<$N$3,E14>=$O$3,E14<$P$3),E14,IF(AND(C14>=$P$3,C14<$N$3,E14>=$P$3,E14<$N$3),"0","none")))))*24 -> 0.79222222
A15: =IF(B15="","",IF(A15="",NOW(),A15)) -> 46221.937 | B15: 带班主任 | C15: 0.93716435 | D15: 完成 | E15: 0.13959491 | F15: =(IF(E15-C15<0,"24:00"-C15+E15,E15-C15))*24 -> 4.8583333 | G15: =F15-H15 -> 1.5080556 | H15: =(IF(AND(C15>=$O$3,C15<$P$3,E15>=$O$3,E15<$P$3),E15-C15,IF(AND(C15>=$O$3,C15<$P$3,E15>=$P$3,E15<$N$3),$P$3-C15,IF(AND(C15>=$P$3,C15<$N$3,E15>=$O$3,E15<$P$3),E15,IF(AND(C15>=$P$3,C15<$N$3,E15>=$P$3,E15<$N$3),"0","none")))))*24 -> 3.3502778 | I15: 统计 | J15: 各席位总小时 | K15: 白班小时 | L15: 夜班小时 (0000-0800) | M15: 备注
A16: =IF(B16="","",IF(A16="",NOW(),A16)) -> 46224.354 | B16: 带班主任 | C16: 0.35371528 | D16: 完成 | E16: 0.52767361 | F16: =(IF(E16-C16<0,"24:00"-C16+E16,E16-C16))*24 -> 4.175 | G16: =F16-H16 -> 4.175 | H16: =(IF(AND(C16>=$O$3,C16<$P$3,E16>=$O$3,E16<$P$3),E16-C16,IF(AND(C16>=$O$3,C16<$P$3,E16>=$P$3,E16<$N$3),$P$3-C16,IF(AND(C16>=$P$3,C16<$N$3,E16>=$O$3,E16<$P$3),E16,IF(AND(C16>=$P$3,C16<$N$3,E16>=$P$3,E16<$N$3),"0","none")))))*24 -> 0 | I16: 带班主任席执勤小时 | J16: =J3 -> 87.653056 | K16: =K3 -> 69.830556 | L16: =L3 -> 17.8225
A17: =IF(B17="","",IF(A17="",NOW(),A17)) -> 46224.656 | B17: 带班主任 | C17: 0.65608796 | D17: 完成 | E17: 0.7859838 | F17: =(IF(E17-C17<0,"24:00"-C17+E17,E17-C17))*24 -> 3.1175 | G17: =F17-H17 -> 3.1175 | H17: =(IF(AND(C17>=$O$3,C17<$P$3,E17>=$O$3,E17<$P$3),E17-C17,IF(AND(C17>=$O$3,C17<$P$3,E17>=$P$3,E17<$N$3),$P$3-C17,IF(AND(C17>=$P$3,C17<$N$3,E17>=$O$3,E17<$P$3),E17,IF(AND(C17>=$P$3,C17<$N$3,E17>=$P$3,E17<$N$3),"0","none")))))*24 -> 0 | I17: 席位执勤小时 | J17: =J4+J5+J6+J7+J10 -> 4.6675 | K17: =K4+K5+K6+K7+K10 -> 1.1502778 | L17: =L4+L5+L6+L7+L10 -> 3.5172222
A18: =IF(B18="","",IF(A18="",NOW(),A18)) -> 46225.523 | B18: 带班主任 | C18: 0.52315972 | D18: 完成 | E18: 0.6528125 | F18: =(IF(E18-C18<0,"24:00"-C18+E18,E18-C18))*24 -> 3.1116667 | G18: =F18-H18 -> 3.1116667 | H18: =(IF(AND(C18>=$O$3,C18<$P$3,E18>=$O$3,E18<$P$3),E18-C18,IF(AND(C18>=$O$3,C18<$P$3,E18>=$P$3,E18<$N$3),$P$3-C18,IF(AND(C18>=$P$3,C18<$N$3,E18>=$O$3,E18<$P$3),E18,IF(AND(C18>=$P$3,C18<$N$3,E18>=$P$3,E18<$N$3),"0","none")))))*24 -> 0 | I18: 见习管制员小时 | J18: =J11 -> 0 | K18: =K11 -> 0 | L18: =L11 -> 0
A19: =IF(B19="","",IF(A19="",NOW(),A19)) -> 46225.749 | B19: 带班主任 | C19: 0.74928241 | D19: 完成 | E19: 0.94325231 | F19: =(IF(E19-C19<0,"24:00"-C19+E19,E19-C19))*24 -> 4.6552778 | G19: =F19-H19 -> 4.6552778 | H19: =(IF(AND(C19>=$O$3,C19<$P$3,E19>=$O$3,E19<$P$3),E19-C19,IF(AND(C19>=$O$3,C19<$P$3,E19>=$P$3,E19<$N$3),$P$3-C19,IF(AND(C19>=$P$3,C19<$N$3,E19>=$O$3,E19<$P$3),E19,IF(AND(C19>=$P$3,C19<$N$3,E19>=$P$3,E19<$N$3),"0","none")))))*24 -> 0 | I19: 管制教员小时 | J19: =J12 -> 0 | K19: =K12 -> 0 | L19: =L12 -> 0
A20: =IF(B20="","",IF(A20="",NOW(),A20)) -> 46226.294 | B20: 带班主任 | C20: 0.29396991 | D20: 完成 | E20: 0.36421296 | F20: =(IF(E20-C20<0,"24:00"-C20+E20,E20-C20))*24 -> 1.6858333 | G20: =F20-H20 -> 0.74111111 | H20: =(IF(AND(C20>=$O$3,C20<$P$3,E20>=$O$3,E20<$P$3),E20-C20,IF(AND(C20>=$O$3,C20<$P$3,E20>=$P$3,E20<$N$3),$P$3-C20,IF(AND(C20>=$P$3,C20<$N$3,E20>=$O$3,E20<$P$3),E20,IF(AND(C20>=$P$3,C20<$N$3,E20>=$P$3,E20<$N$3),"0","none")))))*24 -> 0.94472222 | I20: 月度总小时 | J20: =J16+J17+J18+J19 -> 92.320556
A21: =IF(B21="","",IF(A21="",NOW(),A21)) -> 46228.53 | B21: 带班主任 | C21: 0.52950231 | D21: 完成 | E21: 0.65305556 | F21: =(IF(E21-C21<0,"24:00"-C21+E21,E21-C21))*24 -> 2.9652778 | G21: =F21-H21 -> 2.9652778 | H21: =(IF(AND(C21>=$O$3,C21<$P$3,E21>=$O$3,E21<$P$3),E21-C21,IF(AND(C21>=$O$3,C21<$P$3,E21>=$P$3,E21<$N$3),$P$3-C21,IF(AND(C21>=$P$3,C21<$N$3,E21>=$O$3,E21<$P$3),E21,IF(AND(C21>=$P$3,C21<$N$3,E21>=$P$3,E21<$N$3),"0","none")))))*24 -> 0 | I21: 调度席 | J21: =SUM(J8:J9) -> 0 | K21: =SUM(K8:K9) -> 0 | L21: =SUM(L8:L9) -> 0
A22: =IF(B22="","",IF(A22="",NOW(),A22)) -> 46228.768 | B22: 带班主任 | C22: 0.76771991 | D22: 完成 | E22: 0.94512731 | F22: =(IF(E22-C22<0,"24:00"-C22+E22,E22-C22))*24 -> 4.2577778 | G22: =F22-H22 -> 4.2577778 | H22: =(IF(AND(C22>=$O$3,C22<$P$3,E22>=$O$3,E22<$P$3),E22-C22,IF(AND(C22>=$O$3,C22<$P$3,E22>=$P$3,E22<$N$3),$P$3-C22,IF(AND(C22>=$P$3,C22<$N$3,E22>=$O$3,E22<$P$3),E22,IF(AND(C22>=$P$3,C22<$N$3,E22>=$P$3,E22<$N$3),"0","none")))))*24 -> 0
A23: =IF(B23="","",IF(A23="",NOW(),A23)) -> 46229.297 | B23: 带班主任 | C23: 0.29673611 | D23: 完成 | E23: 0.52837963 | F23: =(IF(E23-C23<0,"24:00"-C23+E23,E23-C23))*24 -> 5.5594444 | G23: =F23-H23 -> 4.6811111 | H23: =(IF(AND(C23>=$O$3,C23<$P$3,E23>=$O$3,E23<$P$3),E23-C23,IF(AND(C23>=$O$3,C23<$P$3,E23>=$P$3,E23<$N$3),$P$3-C23,IF(AND(C23>=$P$3,C23<$N$3,E23>=$O$3,E23<$P$3),E23,IF(AND(C23>=$P$3,C23<$N$3,E23>=$P$3,E23<$N$3),"0","none")))))*24 -> 0.87833333
A24: =IF(B24="","",IF(A24="",NOW(),A24)) -> 46229.647 | B24: 带班主任 | C24: 0.64686343 | D24: 完成 | E24: 0.77898148 | F24: =(IF(E24-C24<0,"24:00"-C24+E24,E24-C24))*24 -> 3.1708333 | G24: =F24-H24 -> 3.1708333 | H24: =(IF(AND(C24>=$O$3,C24<$P$3,E24>=$O$3,E24<$P$3),E24-C24,IF(AND(C24>=$O$3,C24<$P$3,E24>=$P$3,E24<$N$3),$P$3-C24,IF(AND(C24>=$P$3,C24<$N$3,E24>=$O$3,E24<$P$3),E24,IF(AND(C24>=$P$3,C24<$N$3,E24>=$P$3,E24<$N$3),"0","none")))))*24 -> 0
A25: =IF(B25="","",IF(A25="",NOW(),A25)) -> 46232.952 | B25: 带班主任 | C25: 0.95232639 | D25: 完成 | E25: 0.14487269 | F25: =(IF(E25-C25<0,"24:00"-C25+E25,E25-C25))*24 -> 4.6211111 | G25: =F25-H25 -> 1.1441667 | H25: =(IF(AND(C25>=$O$3,C25<$P$3,E25>=$O$3,E25<$P$3),E25-C25,IF(AND(C25>=$O$3,C25<$P$3,E25>=$P$3,E25<$N$3),$P$3-C25,IF(AND(C25>=$P$3,C25<$N$3,E25>=$O$3,E25<$P$3),E25,IF(AND(C25>=$P$3,C25<$N$3,E25>=$P$3,E25<$N$3),"0","none")))))*24 -> 3.4769444
A26: =IF(B26="","",IF(A26="",NOW(),A26)) -> 46234.147 | B26: 东塔台管制席 | C26: 0.95207176 | D26: 完成 | E26: 0.14655093 | F26: =(IF(E26-C26<0,"24:00"-C26+E26,E26-C26))*24 -> 4.6675 | G26: =F26-H26 -> 1.1502778 | H26: =(IF(AND(C26>=$O$3,C26<$P$3,E26>=$O$3,E26<$P$3),E26-C26,IF(AND(C26>=$O$3,C26<$P$3,E26>=$P$3,E26<$N$3),$P$3-C26,IF(AND(C26>=$P$3,C26<$N$3,E26>=$O$3,E26<$P$3),E26,IF(AND(C26>=$P$3,C26<$N$3,E26>=$P$3,E26<$N$3),"0","none")))))*24 -> 3.5172222
A27: =IF(B27="","",IF(A27="",NOW(),A27)) | F27: =(IF(E27-C27<0,"24:00"-C27+E27,E27-C27))*24 -> 0 | G27: =F27-H27 -> 0 | H27: =(IF(AND(C27>=$O$3,C27<$P$3,E27>=$O$3,E27<$P$3),E27-C27,IF(AND(C27>=$O$3,C27<$P$3,E27>=$P$3,E27<$N$3),$P$3-C27,IF(AND(C27>=$P$3,C27<$N$3,E27>=$O$3,E27<$P$3),E27,IF(AND(C27>=$P$3,C27<$N$3,E27>=$P$3,E27<$N$3),"0","none")))))*24 -> 0
A28: =IF(B28="","",IF(A28="",NOW(),A28)) | F28: =(IF(E28-C28<0,"24:00"-C28+E28,E28-C28))*24 -> 0 | G28: =F28-H28 -> 0 | H28: =(IF(AND(C28>=$O$3,C28<$P$3,E28>=$O$3,E28<$P$3),E28-C28,IF(AND(C28>=$O$3,C28<$P$3,E28>=$P$3,E28<$N$3),$P$3-C28,IF(AND(C28>=$P$3,C28<$N$3,E28>=$O$3,E28<$P$3),E28,IF(AND(C28>=$P$3,C28<$N$3,E28>=$P$3,E28<$N$3),"0","none")))))*24 -> 0
A29: =IF(B29="","",IF(A29="",NOW(),A29)) | F29: =(IF(E29-C29<0,"24:00"-C29+E29,E29-C29))*24 -> 0 | G29: =F29-H29 -> 0 | H29: =(IF(AND(C29>=$O$3,C29<$P$3,E29>=$O$3,E29<$P$3),E29-C29,IF(AND(C29>=$O$3,C29<$P$3,E29>=$P$3,E29<$N$3),$P$3-C29,IF(AND(C29>=$P$3,C29<$N$3,E29>=$O$3,E29<$P$3),E29,IF(AND(C29>=$P$3,C29<$N$3,E29>=$P$3,E29<$N$3),"0","none")))))*24 -> 0
A30: =IF(B30="","",IF(A30="",NOW(),A30)) | F30: =(IF(E30-C30<0,"24:00"-C30+E30,E30-C30))*24 -> 0 | G30: =F30-H30 -> 0 | H30: =(IF(AND(C30>=$O$3,C30<$P$3,E30>=$O$3,E30<$P$3),E30-C30,IF(AND(C30>=$O$3,C30<$P$3,E30>=$P$3,E30<$N$3),$P$3-C30,IF(AND(C30>=$P$3,C30<$N$3,E30>=$O$3,E30<$P$3),E30,IF(AND(C30>=$P$3,C30<$N$3,E30>=$P$3,E30<$N$3),"0","none")))))*24 -> 0
A31: =IF(B31="","",IF(A31="",NOW(),A31)) | F31: =(IF(E31-C31<0,"24:00"-C31+E31,E31-C31))*24 -> 0 | G31: =F31-H31 -> 0 | H31: =(IF(AND(C31>=$O$3,C31<$P$3,E31>=$O$3,E31<$P$3),E31-C31,IF(AND(C31>=$O$3,C31<$P$3,E31>=$P$3,E31<$N$3),$P$3-C31,IF(AND(C31>=$P$3,C31<$N$3,E31>=$O$3,E31<$P$3),E31,IF(AND(C31>=$P$3,C31<$N$3,E31>=$P$3,E31<$N$3),"0","none")))))*24 -> 0
A32: =IF(B32="","",IF(A32="",NOW(),A32)) | F32: =(IF(E32-C32<0,"24:00"-C32+E32,E32-C32))*24 -> 0 | G32: =F32-H32 -> 0 | H32: =(IF(AND(C32>=$O$3,C32<$P$3,E32>=$O$3,E32<$P$3),E32-C32,IF(AND(C32>=$O$3,C32<$P$3,E32>=$P$3,E32<$N$3),$P$3-C32,IF(AND(C32>=$P$3,C32<$N$3,E32>=$O$3,E32<$P$3),E32,IF(AND(C32>=$P$3,C32<$N$3,E32>=$P$3,E32<$N$3),"0","none")))))*24 -> 0
A33: =IF(B33="","",IF(A33="",NOW(),A33)) | F33: =(IF(E33-C33<0,"24:00"-C33+E33,E33-C33))*24 -> 0 | G33: =F33-H33 -> 0 | H33: =(IF(AND(C33>=$O$3,C33<$P$3,E33>=$O$3,E33<$P$3),E33-C33,IF(AND(C33>=$O$3,C33<$P$3,E33>=$P$3,E33<$N$3),$P$3-C33,IF(AND(C33>=$P$3,C33<$N$3,E33>=$O$3,E33<$P$3),E33,IF(AND(C33>=$P$3,C33<$N$3,E33>=$P$3,E33<$N$3),"0","none")))))*24 -> 0
A34: =IF(B34="","",IF(A34="",NOW(),A34)) | F34: =(IF(E34-C34<0,"24:00"-C34+E34,E34-C34))*24 -> 0 | G34: =F34-H34 -> 0 | H34: =(IF(AND(C34>=$O$3,C34<$P$3,E34>=$O$3,E34<$P$3),E34-C34,IF(AND(C34>=$O$3,C34<$P$3,E34>=$P$3,E34<$N$3),$P$3-C34,IF(AND(C34>=$P$3,C34<$N$3,E34>=$O$3,E34<$P$3),E34,IF(AND(C34>=$P$3,C34<$N$3,E34>=$P$3,E34<$N$3),"0","none")))))*24 -> 0
A35: =IF(B35="","",IF(A35="",NOW(),A35)) | F35: =(IF(E35-C35<0,"24:00"-C35+E35,E35-C35))*24 -> 0 | G35: =F35-H35 -> 0 | H35: =(IF(AND(C35>=$O$3,C35<$P$3,E35>=$O$3,E35<$P$3),E35-C35,IF(AND(C35>=$O$3,C35<$P$3,E35>=$P$3,E35<$N$3),$P$3-C35,IF(AND(C35>=$P$3,C35<$N$3,E35>=$O$3,E35<$P$3),E35,IF(AND(C35>=$P$3,C35<$N$3,E35>=$P$3,E35<$N$3),"0","none")))))*24 -> 0
A36: =IF(B36="","",IF(A36="",NOW(),A36)) | F36: =(IF(E36-C36<0,"24:00"-C36+E36,E36-C36))*24 -> 0 | G36: =F36-H36 -> 0 | H36: =(IF(AND(C36>=$O$3,C36<$P$3,E36>=$O$3,E36<$P$3),E36-C36,IF(AND(C36>=$O$3,C36<$P$3,E36>=$P$3,E36<$N$3),$P$3-C36,IF(AND(C36>=$P$3,C36<$N$3,E36>=$O$3,E36<$P$3),E36,IF(AND(C36>=$P$3,C36<$N$3,E36>=$P$3,E36<$N$3),"0","none")))))*24 -> 0
A37: =IF(B37="","",IF(A37="",NOW(),A37)) | F37: =(IF(E37-C37<0,"24:00"-C37+E37,E37-C37))*24 -> 0 | G37: =F37-H37 -> 0 | H37: =(IF(AND(C37>=$O$3,C37<$P$3,E37>=$O$3,E37<$P$3),E37-C37,IF(AND(C37>=$O$3,C37<$P$3,E37>=$P$3,E37<$N$3),$P$3-C37,IF(AND(C37>=$P$3,C37<$N$3,E37>=$O$3,E37<$P$3),E37,IF(AND(C37>=$P$3,C37<$N$3,E37>=$P$3,E37<$N$3),"0","none")))))*24 -> 0
